package com.wuppy.goblinsgiants.worldgen;

import java.util.Random;

import net.minecraft.init.Blocks;
import net.minecraft.tileentity.TileEntityChest;
import net.minecraft.tileentity.TileEntityMobSpawner;
import net.minecraft.util.WeightedRandomChestContent;
import net.minecraft.world.World;
import net.minecraft.world.biome.BiomeGenBase;
import net.minecraft.world.gen.feature.WorldGenerator;
import net.minecraftforge.common.ChestGenHooks;

import com.wuppy.goblinsgiants.blocks.ModBlocks;

public class WorldGenSavannahEntranceTemple extends WorldGenerator
{
	public WorldGenSavannahEntranceTemple()
	{
	}

	public boolean generate(World world, Random rand, int x, int y, int z)
	{
		if (world.getBiomeGenForCoords(x, z) != BiomeGenBase.desert && world.getBiomeGenForCoords(x, z) != BiomeGenBase.desertHills)
		{
			return false;
		}
		
		if(y < 50 || y > 80 || world.getBlock(x + 10, y + 15, z + 20) != Blocks.sand || world.getBlock(x + 10, y + 16, z + 20) != Blocks.air)
			return false;
		
		world.setBlock(x + 0, y + 0, z + 0, Blocks.sandstone);
		world.setBlock(x + 0, y + 0, z + 1, Blocks.sandstone);
		world.setBlock(x + 0, y + 0, z + 2, Blocks.sandstone);
		world.setBlock(x + 0, y + 0, z + 3, Blocks.sandstone);
		world.setBlock(x + 0, y + 0, z + 4, Blocks.sandstone);
		world.setBlock(x + 0, y + 0, z + 5, Blocks.sandstone);
		world.setBlock(x + 0, y + 0, z + 6, Blocks.sandstone);
		world.setBlock(x + 0, y + 0, z + 7, Blocks.sandstone);
		world.setBlock(x + 0, y + 0, z + 8, Blocks.sandstone);
		world.setBlock(x + 0, y + 0, z + 9, Blocks.sandstone);
		world.setBlock(x + 0, y + 0, z + 10, Blocks.sandstone);
		world.setBlock(x + 0, y + 0, z + 11, Blocks.sandstone);
		world.setBlock(x + 0, y + 0, z + 12, Blocks.sandstone);
		world.setBlock(x + 0, y + 0, z + 13, Blocks.sandstone);
		world.setBlock(x + 0, y + 0, z + 14, Blocks.sandstone);
		world.setBlock(x + 0, y + 0, z + 15, Blocks.sandstone);
		world.setBlock(x + 0, y + 0, z + 16, Blocks.sandstone);
		world.setBlock(x + 0, y + 0, z + 17, Blocks.sandstone);
		world.setBlock(x + 0, y + 0, z + 18, Blocks.sandstone);
		world.setBlock(x + 0, y + 0, z + 19, Blocks.sandstone);
		world.setBlock(x + 0, y + 0, z + 20, Blocks.sandstone);
		world.setBlock(x + 0, y + 1, z + 0, Blocks.sandstone);
		world.setBlock(x + 0, y + 1, z + 1, Blocks.sandstone);
		world.setBlock(x + 0, y + 1, z + 2, Blocks.sandstone);
		world.setBlock(x + 0, y + 1, z + 3, Blocks.sandstone);
		world.setBlock(x + 0, y + 1, z + 4, Blocks.sandstone);
		world.setBlock(x + 0, y + 1, z + 5, Blocks.sandstone);
		world.setBlock(x + 0, y + 1, z + 6, Blocks.sandstone);
		world.setBlock(x + 0, y + 1, z + 7, Blocks.sandstone);
		world.setBlock(x + 0, y + 1, z + 8, Blocks.sandstone);
		world.setBlock(x + 0, y + 1, z + 9, Blocks.sandstone);
		world.setBlock(x + 0, y + 1, z + 10, Blocks.sandstone);
		world.setBlock(x + 0, y + 1, z + 11, Blocks.sandstone);
		world.setBlock(x + 0, y + 1, z + 12, Blocks.sandstone);
		world.setBlock(x + 0, y + 1, z + 13, Blocks.sandstone);
		world.setBlock(x + 0, y + 1, z + 14, Blocks.sandstone);
		world.setBlock(x + 0, y + 1, z + 15, Blocks.sandstone);
		world.setBlock(x + 0, y + 1, z + 16, Blocks.sandstone);
		world.setBlock(x + 0, y + 1, z + 17, Blocks.sandstone);
		world.setBlock(x + 0, y + 1, z + 18, Blocks.sandstone);
		world.setBlock(x + 0, y + 1, z + 19, Blocks.sandstone);
		world.setBlock(x + 0, y + 1, z + 20, Blocks.sandstone);
		world.setBlock(x + 0, y + 2, z + 0, Blocks.sandstone);
		world.setBlock(x + 0, y + 2, z + 1, Blocks.sandstone);
		world.setBlock(x + 0, y + 2, z + 2, Blocks.sandstone);
		world.setBlock(x + 0, y + 2, z + 3, Blocks.sandstone);
		world.setBlock(x + 0, y + 2, z + 4, Blocks.sandstone);
		world.setBlock(x + 0, y + 2, z + 5, Blocks.sandstone);
		world.setBlock(x + 0, y + 2, z + 6, Blocks.sandstone);
		world.setBlock(x + 0, y + 2, z + 7, Blocks.sandstone);
		world.setBlock(x + 0, y + 2, z + 8, Blocks.sandstone);
		world.setBlock(x + 0, y + 2, z + 9, Blocks.sandstone);
		world.setBlock(x + 0, y + 2, z + 10, Blocks.sandstone);
		world.setBlock(x + 0, y + 2, z + 11, Blocks.sandstone);
		world.setBlock(x + 0, y + 2, z + 12, Blocks.sandstone);
		world.setBlock(x + 0, y + 2, z + 13, Blocks.sandstone);
		world.setBlock(x + 0, y + 2, z + 14, Blocks.sandstone);
		world.setBlock(x + 0, y + 2, z + 15, Blocks.sandstone);
		world.setBlock(x + 0, y + 2, z + 16, Blocks.sandstone);
		world.setBlock(x + 0, y + 2, z + 17, Blocks.sandstone);
		world.setBlock(x + 0, y + 2, z + 18, Blocks.sandstone);
		world.setBlock(x + 0, y + 2, z + 19, Blocks.sandstone);
		world.setBlock(x + 0, y + 2, z + 20, Blocks.sandstone);
		world.setBlock(x + 0, y + 3, z + 0, Blocks.sandstone);
		world.setBlock(x + 0, y + 3, z + 1, Blocks.sandstone);
		world.setBlock(x + 0, y + 3, z + 2, Blocks.sandstone);
		world.setBlock(x + 0, y + 3, z + 3, Blocks.sandstone);
		world.setBlock(x + 0, y + 3, z + 4, Blocks.sandstone);
		world.setBlock(x + 0, y + 3, z + 5, Blocks.sandstone);
		world.setBlock(x + 0, y + 3, z + 6, Blocks.sandstone);
		world.setBlock(x + 0, y + 3, z + 7, Blocks.sandstone);
		world.setBlock(x + 0, y + 3, z + 8, Blocks.sandstone);
		world.setBlock(x + 0, y + 3, z + 9, Blocks.sandstone);
		world.setBlock(x + 0, y + 3, z + 10, Blocks.sandstone);
		world.setBlock(x + 0, y + 3, z + 11, Blocks.sandstone);
		world.setBlock(x + 0, y + 3, z + 12, Blocks.sandstone);
		world.setBlock(x + 0, y + 3, z + 13, Blocks.sandstone);
		world.setBlock(x + 0, y + 3, z + 14, Blocks.sandstone);
		world.setBlock(x + 0, y + 3, z + 15, Blocks.sandstone);
		world.setBlock(x + 0, y + 3, z + 16, Blocks.sandstone);
		world.setBlock(x + 0, y + 3, z + 17, Blocks.sandstone);
		world.setBlock(x + 0, y + 3, z + 18, Blocks.sandstone);
		world.setBlock(x + 0, y + 3, z + 19, Blocks.sandstone);
		world.setBlock(x + 0, y + 3, z + 20, Blocks.sandstone);
		world.setBlock(x + 0, y + 4, z + 0, Blocks.sandstone);
		world.setBlock(x + 0, y + 4, z + 1, Blocks.sandstone);
		world.setBlock(x + 0, y + 4, z + 2, Blocks.sandstone);
		world.setBlock(x + 0, y + 4, z + 3, Blocks.sandstone);
		world.setBlock(x + 0, y + 4, z + 4, Blocks.sandstone);
		world.setBlock(x + 0, y + 4, z + 5, Blocks.sandstone);
		world.setBlock(x + 0, y + 4, z + 6, Blocks.sandstone);
		world.setBlock(x + 0, y + 4, z + 7, Blocks.sandstone);
		world.setBlock(x + 0, y + 4, z + 8, Blocks.sandstone);
		world.setBlock(x + 0, y + 4, z + 9, Blocks.sandstone);
		world.setBlock(x + 0, y + 4, z + 10, Blocks.sandstone);
		world.setBlock(x + 0, y + 4, z + 11, Blocks.sandstone);
		world.setBlock(x + 0, y + 4, z + 12, Blocks.sandstone);
		world.setBlock(x + 0, y + 4, z + 13, Blocks.sandstone);
		world.setBlock(x + 0, y + 4, z + 14, Blocks.sandstone);
		world.setBlock(x + 0, y + 4, z + 15, Blocks.sandstone);
		world.setBlock(x + 0, y + 4, z + 16, Blocks.sandstone);
		world.setBlock(x + 0, y + 4, z + 17, Blocks.sandstone);
		world.setBlock(x + 0, y + 4, z + 18, Blocks.sandstone);
		world.setBlock(x + 0, y + 4, z + 19, Blocks.sandstone);
		world.setBlock(x + 0, y + 4, z + 20, Blocks.sandstone);
		world.setBlock(x + 0, y + 5, z + 0, Blocks.sandstone);
		world.setBlock(x + 0, y + 5, z + 1, Blocks.sandstone);
		world.setBlock(x + 0, y + 5, z + 2, Blocks.sandstone);
		world.setBlock(x + 0, y + 5, z + 3, Blocks.sandstone);
		world.setBlock(x + 0, y + 5, z + 4, Blocks.sandstone);
		world.setBlock(x + 0, y + 5, z + 5, Blocks.sandstone);
		world.setBlock(x + 0, y + 5, z + 6, Blocks.sandstone);
		world.setBlock(x + 0, y + 5, z + 7, Blocks.sandstone);
		world.setBlock(x + 0, y + 5, z + 8, Blocks.sandstone);
		world.setBlock(x + 0, y + 5, z + 9, Blocks.sandstone);
		world.setBlock(x + 0, y + 5, z + 10, Blocks.sandstone);
		world.setBlock(x + 0, y + 5, z + 11, Blocks.sandstone);
		world.setBlock(x + 0, y + 5, z + 12, Blocks.sandstone);
		world.setBlock(x + 0, y + 5, z + 13, Blocks.sandstone);
		world.setBlock(x + 0, y + 5, z + 14, Blocks.sandstone);
		world.setBlock(x + 0, y + 5, z + 15, Blocks.sandstone);
		world.setBlock(x + 0, y + 5, z + 16, Blocks.sandstone);
		world.setBlock(x + 0, y + 5, z + 17, Blocks.sandstone);
		world.setBlock(x + 0, y + 5, z + 18, Blocks.sandstone);
		world.setBlock(x + 0, y + 5, z + 19, Blocks.sandstone);
		world.setBlock(x + 0, y + 5, z + 20, Blocks.sandstone);
		world.setBlock(x + 0, y + 6, z + 0, Blocks.sandstone);
		world.setBlock(x + 0, y + 6, z + 1, Blocks.sandstone);
		world.setBlock(x + 0, y + 6, z + 2, Blocks.sandstone);
		world.setBlock(x + 0, y + 6, z + 3, Blocks.sandstone);
		world.setBlock(x + 0, y + 6, z + 4, Blocks.sandstone);
		world.setBlock(x + 0, y + 6, z + 5, Blocks.sandstone);
		world.setBlock(x + 0, y + 6, z + 6, Blocks.sandstone);
		world.setBlock(x + 0, y + 6, z + 7, Blocks.sandstone);
		world.setBlock(x + 0, y + 6, z + 8, Blocks.sandstone);
		world.setBlock(x + 0, y + 6, z + 9, Blocks.sandstone);
		world.setBlock(x + 0, y + 6, z + 10, Blocks.sandstone);
		world.setBlock(x + 0, y + 6, z + 11, Blocks.sandstone);
		world.setBlock(x + 0, y + 6, z + 12, Blocks.sandstone);
		world.setBlock(x + 0, y + 6, z + 13, Blocks.sandstone);
		world.setBlock(x + 0, y + 6, z + 14, Blocks.sandstone);
		world.setBlock(x + 0, y + 6, z + 15, Blocks.sandstone);
		world.setBlock(x + 0, y + 6, z + 16, Blocks.sandstone);
		world.setBlock(x + 0, y + 6, z + 17, Blocks.sandstone);
		world.setBlock(x + 0, y + 6, z + 18, Blocks.sandstone);
		world.setBlock(x + 0, y + 6, z + 19, Blocks.sandstone);
		world.setBlock(x + 0, y + 6, z + 20, Blocks.sandstone);
		world.setBlock(x + 0, y + 7, z + 0, Blocks.sandstone);
		world.setBlock(x + 0, y + 7, z + 1, Blocks.sandstone);
		world.setBlock(x + 0, y + 7, z + 2, Blocks.sandstone);
		world.setBlock(x + 0, y + 7, z + 3, Blocks.sandstone);
		world.setBlock(x + 0, y + 7, z + 4, Blocks.sandstone);
		world.setBlock(x + 0, y + 7, z + 5, Blocks.sandstone);
		world.setBlock(x + 0, y + 7, z + 6, Blocks.sandstone);
		world.setBlock(x + 0, y + 7, z + 7, Blocks.sandstone);
		world.setBlock(x + 0, y + 7, z + 8, Blocks.sandstone);
		world.setBlock(x + 0, y + 7, z + 9, Blocks.sandstone);
		world.setBlock(x + 0, y + 7, z + 10, Blocks.sandstone);
		world.setBlock(x + 0, y + 7, z + 11, Blocks.sandstone);
		world.setBlock(x + 0, y + 7, z + 12, Blocks.sandstone);
		world.setBlock(x + 0, y + 7, z + 13, Blocks.sandstone);
		world.setBlock(x + 0, y + 7, z + 14, Blocks.sandstone);
		world.setBlock(x + 0, y + 7, z + 15, Blocks.sandstone);
		world.setBlock(x + 0, y + 7, z + 16, Blocks.sandstone);
		world.setBlock(x + 0, y + 7, z + 17, Blocks.sandstone);
		world.setBlock(x + 0, y + 7, z + 18, Blocks.sandstone);
		world.setBlock(x + 0, y + 7, z + 19, Blocks.sandstone);
		world.setBlock(x + 0, y + 7, z + 20, Blocks.sandstone);
		world.setBlock(x + 0, y + 8, z + 0, Blocks.sandstone);
		world.setBlock(x + 0, y + 8, z + 1, Blocks.sandstone);
		world.setBlock(x + 0, y + 8, z + 2, Blocks.sandstone);
		world.setBlock(x + 0, y + 8, z + 3, Blocks.sandstone);
		world.setBlock(x + 0, y + 8, z + 4, Blocks.sandstone);
		world.setBlock(x + 0, y + 8, z + 5, Blocks.sandstone);
		world.setBlock(x + 0, y + 8, z + 6, Blocks.sandstone);
		world.setBlock(x + 0, y + 8, z + 7, Blocks.sandstone);
		world.setBlock(x + 0, y + 8, z + 8, Blocks.sandstone);
		world.setBlock(x + 0, y + 8, z + 9, Blocks.sandstone);
		world.setBlock(x + 0, y + 8, z + 10, Blocks.sandstone);
		world.setBlock(x + 0, y + 8, z + 11, Blocks.sandstone);
		world.setBlock(x + 0, y + 8, z + 12, Blocks.sandstone);
		world.setBlock(x + 0, y + 8, z + 13, Blocks.sandstone);
		world.setBlock(x + 0, y + 8, z + 14, Blocks.sandstone);
		world.setBlock(x + 0, y + 8, z + 15, Blocks.sandstone);
		world.setBlock(x + 0, y + 8, z + 16, Blocks.sandstone);
		world.setBlock(x + 0, y + 8, z + 17, Blocks.sandstone);
		world.setBlock(x + 0, y + 8, z + 18, Blocks.sandstone);
		world.setBlock(x + 0, y + 8, z + 19, Blocks.sandstone);
		world.setBlock(x + 0, y + 8, z + 20, Blocks.sandstone);
		world.setBlock(x + 0, y + 9, z + 0, Blocks.sandstone);
		world.setBlock(x + 0, y + 9, z + 1, Blocks.sandstone);
		world.setBlock(x + 0, y + 9, z + 2, Blocks.sandstone);
		world.setBlock(x + 0, y + 9, z + 3, Blocks.sandstone);
		world.setBlock(x + 0, y + 9, z + 4, Blocks.sandstone);
		world.setBlock(x + 0, y + 9, z + 5, Blocks.sandstone);
		world.setBlock(x + 0, y + 9, z + 6, Blocks.sandstone);
		world.setBlock(x + 0, y + 9, z + 7, Blocks.sandstone);
		world.setBlock(x + 0, y + 9, z + 8, Blocks.sandstone);
		world.setBlock(x + 0, y + 9, z + 9, Blocks.sandstone);
		world.setBlock(x + 0, y + 9, z + 10, Blocks.sandstone);
		world.setBlock(x + 0, y + 9, z + 11, Blocks.sandstone);
		world.setBlock(x + 0, y + 9, z + 12, Blocks.sandstone);
		world.setBlock(x + 0, y + 9, z + 13, Blocks.sandstone);
		world.setBlock(x + 0, y + 9, z + 14, Blocks.sandstone);
		world.setBlock(x + 0, y + 9, z + 15, Blocks.sandstone);
		world.setBlock(x + 0, y + 9, z + 16, Blocks.sandstone);
		world.setBlock(x + 0, y + 9, z + 17, Blocks.sandstone);
		world.setBlock(x + 0, y + 9, z + 18, Blocks.sandstone);
		world.setBlock(x + 0, y + 9, z + 19, Blocks.sandstone);
		world.setBlock(x + 0, y + 9, z + 20, Blocks.sandstone);
		world.setBlock(x + 0, y + 10, z + 0, Blocks.sandstone);
		world.setBlock(x + 0, y + 10, z + 1, Blocks.sandstone);
		world.setBlock(x + 0, y + 10, z + 2, Blocks.sandstone);
		world.setBlock(x + 0, y + 10, z + 3, Blocks.sandstone);
		world.setBlock(x + 0, y + 10, z + 4, Blocks.sandstone);
		world.setBlock(x + 0, y + 10, z + 5, Blocks.sandstone);
		world.setBlock(x + 0, y + 10, z + 6, Blocks.sandstone);
		world.setBlock(x + 0, y + 10, z + 7, Blocks.sandstone);
		world.setBlock(x + 0, y + 10, z + 8, Blocks.sandstone);
		world.setBlock(x + 0, y + 10, z + 9, Blocks.sandstone);
		world.setBlock(x + 0, y + 10, z + 10, Blocks.sandstone);
		world.setBlock(x + 0, y + 10, z + 11, Blocks.sandstone);
		world.setBlock(x + 0, y + 10, z + 12, Blocks.sandstone);
		world.setBlock(x + 0, y + 10, z + 13, Blocks.sandstone);
		world.setBlock(x + 0, y + 10, z + 14, Blocks.sandstone);
		world.setBlock(x + 0, y + 10, z + 15, Blocks.sandstone);
		world.setBlock(x + 0, y + 10, z + 16, Blocks.sandstone);
		world.setBlock(x + 0, y + 10, z + 17, Blocks.sandstone);
		world.setBlock(x + 0, y + 10, z + 18, Blocks.sandstone);
		world.setBlock(x + 0, y + 10, z + 19, Blocks.sandstone);
		world.setBlock(x + 0, y + 10, z + 20, Blocks.sandstone);
		world.setBlock(x + 0, y + 11, z + 0, Blocks.sandstone);
		world.setBlock(x + 0, y + 11, z + 1, Blocks.sandstone);
		world.setBlock(x + 0, y + 11, z + 2, Blocks.sandstone);
		world.setBlock(x + 0, y + 11, z + 3, Blocks.sandstone);
		world.setBlock(x + 0, y + 11, z + 4, Blocks.sandstone);
		world.setBlock(x + 0, y + 11, z + 5, Blocks.sandstone);
		world.setBlock(x + 0, y + 11, z + 6, Blocks.sandstone);
		world.setBlock(x + 0, y + 11, z + 7, Blocks.sandstone);
		world.setBlock(x + 0, y + 11, z + 8, Blocks.sandstone);
		world.setBlock(x + 0, y + 11, z + 9, Blocks.sandstone);
		world.setBlock(x + 0, y + 11, z + 10, Blocks.sandstone);
		world.setBlock(x + 0, y + 11, z + 11, Blocks.sandstone);
		world.setBlock(x + 0, y + 11, z + 12, Blocks.sandstone);
		world.setBlock(x + 0, y + 11, z + 13, Blocks.sandstone);
		world.setBlock(x + 0, y + 11, z + 14, Blocks.sandstone);
		world.setBlock(x + 0, y + 11, z + 15, Blocks.sandstone);
		world.setBlock(x + 0, y + 11, z + 16, Blocks.sandstone);
		world.setBlock(x + 0, y + 11, z + 17, Blocks.sandstone);
		world.setBlock(x + 0, y + 11, z + 18, Blocks.sandstone);
		world.setBlock(x + 0, y + 11, z + 19, Blocks.sandstone);
		world.setBlock(x + 0, y + 11, z + 20, Blocks.sandstone);
		world.setBlock(x + 0, y + 12, z + 0, Blocks.sandstone);
		world.setBlock(x + 0, y + 12, z + 1, Blocks.sandstone);
		world.setBlock(x + 0, y + 12, z + 2, Blocks.sandstone);
		world.setBlock(x + 0, y + 12, z + 3, Blocks.sandstone);
		world.setBlock(x + 0, y + 12, z + 4, Blocks.sandstone);
		world.setBlock(x + 0, y + 12, z + 5, Blocks.sandstone);
		world.setBlock(x + 0, y + 12, z + 6, Blocks.sandstone);
		world.setBlock(x + 0, y + 12, z + 7, Blocks.sandstone);
		world.setBlock(x + 0, y + 12, z + 8, Blocks.sandstone);
		world.setBlock(x + 0, y + 12, z + 9, Blocks.sandstone);
		world.setBlock(x + 0, y + 12, z + 10, Blocks.sandstone);
		world.setBlock(x + 0, y + 12, z + 11, Blocks.sandstone);
		world.setBlock(x + 0, y + 12, z + 12, Blocks.sandstone);
		world.setBlock(x + 0, y + 12, z + 13, Blocks.sandstone);
		world.setBlock(x + 0, y + 12, z + 14, Blocks.sandstone);
		world.setBlock(x + 0, y + 12, z + 15, Blocks.sandstone);
		world.setBlock(x + 0, y + 12, z + 16, Blocks.sandstone);
		world.setBlock(x + 0, y + 12, z + 17, Blocks.sandstone);
		world.setBlock(x + 0, y + 12, z + 18, Blocks.sandstone);
		world.setBlock(x + 0, y + 12, z + 19, Blocks.sandstone);
		world.setBlock(x + 0, y + 12, z + 20, Blocks.sandstone);
		world.setBlock(x + 0, y + 13, z + 0, Blocks.sandstone);
		world.setBlock(x + 0, y + 13, z + 1, Blocks.sandstone);
		world.setBlock(x + 0, y + 13, z + 2, Blocks.sandstone);
		world.setBlock(x + 0, y + 13, z + 3, Blocks.sandstone);
		world.setBlock(x + 0, y + 13, z + 4, Blocks.sandstone);
		world.setBlock(x + 0, y + 13, z + 5, Blocks.sandstone);
		world.setBlock(x + 0, y + 13, z + 6, Blocks.sandstone);
		world.setBlock(x + 0, y + 13, z + 7, Blocks.sandstone);
		world.setBlock(x + 0, y + 13, z + 8, Blocks.sandstone);
		world.setBlock(x + 0, y + 13, z + 9, Blocks.sandstone);
		world.setBlock(x + 0, y + 13, z + 10, Blocks.sandstone);
		world.setBlock(x + 0, y + 13, z + 11, Blocks.sandstone);
		world.setBlock(x + 0, y + 13, z + 12, Blocks.sandstone);
		world.setBlock(x + 0, y + 13, z + 13, Blocks.sandstone);
		world.setBlock(x + 0, y + 13, z + 14, Blocks.sandstone);
		world.setBlock(x + 0, y + 13, z + 15, Blocks.sandstone);
		world.setBlock(x + 0, y + 13, z + 16, Blocks.sandstone);
		world.setBlock(x + 0, y + 13, z + 17, Blocks.sandstone);
		world.setBlock(x + 0, y + 13, z + 18, Blocks.sandstone);
		world.setBlock(x + 0, y + 13, z + 19, Blocks.sandstone);
		world.setBlock(x + 0, y + 13, z + 20, Blocks.sandstone);
		world.setBlock(x + 0, y + 14, z + 0, Blocks.air);
		world.setBlock(x + 0, y + 14, z + 1, Blocks.air);
		world.setBlock(x + 0, y + 14, z + 2, Blocks.air);
		world.setBlock(x + 0, y + 14, z + 3, Blocks.air);
		world.setBlock(x + 0, y + 14, z + 4, Blocks.air);
		world.setBlock(x + 0, y + 14, z + 5, Blocks.air);
		world.setBlock(x + 0, y + 14, z + 6, Blocks.air);
		world.setBlock(x + 0, y + 14, z + 7, Blocks.air);
		world.setBlock(x + 0, y + 14, z + 8, Blocks.air);
		world.setBlock(x + 0, y + 14, z + 9, Blocks.air);
		world.setBlock(x + 0, y + 14, z + 10, Blocks.air);
		world.setBlock(x + 0, y + 14, z + 11, Blocks.air);
		world.setBlock(x + 0, y + 14, z + 12, Blocks.air);
		world.setBlock(x + 0, y + 14, z + 13, Blocks.air);
		world.setBlock(x + 0, y + 14, z + 14, Blocks.air);
		world.setBlock(x + 0, y + 14, z + 15, Blocks.air);
		world.setBlock(x + 0, y + 14, z + 16, Blocks.sandstone);
		world.setBlock(x + 0, y + 14, z + 17, Blocks.sandstone);
		world.setBlock(x + 0, y + 14, z + 18, Blocks.sandstone);
		world.setBlock(x + 0, y + 14, z + 19, Blocks.sandstone);
		world.setBlock(x + 0, y + 14, z + 20, Blocks.sandstone);
		world.setBlock(x + 0, y + 15, z + 0, Blocks.air);
		world.setBlock(x + 0, y + 15, z + 1, Blocks.air);
		world.setBlock(x + 0, y + 15, z + 2, Blocks.air);
		world.setBlock(x + 0, y + 15, z + 3, Blocks.air);
		world.setBlock(x + 0, y + 15, z + 4, Blocks.air);
		world.setBlock(x + 0, y + 15, z + 5, Blocks.air);
		world.setBlock(x + 0, y + 15, z + 6, Blocks.air);
		world.setBlock(x + 0, y + 15, z + 7, Blocks.air);
		world.setBlock(x + 0, y + 15, z + 8, Blocks.air);
		world.setBlock(x + 0, y + 15, z + 9, Blocks.air);
		world.setBlock(x + 0, y + 15, z + 10, Blocks.air);
		world.setBlock(x + 0, y + 15, z + 11, Blocks.air);
		world.setBlock(x + 0, y + 15, z + 12, Blocks.air);
		world.setBlock(x + 0, y + 15, z + 13, Blocks.air);
		world.setBlock(x + 0, y + 15, z + 14, Blocks.air);
		world.setBlock(x + 0, y + 15, z + 15, Blocks.air);
		world.setBlock(x + 0, y + 15, z + 16, Blocks.sandstone);
		world.setBlock(x + 0, y + 15, z + 17, Blocks.sandstone, 2, 2);
		world.setBlock(x + 0, y + 15, z + 18, Blocks.wool, 14, 2);
		world.setBlock(x + 0, y + 15, z + 19, Blocks.sandstone, 2, 2);
		world.setBlock(x + 0, y + 15, z + 20, Blocks.sandstone);
		world.setBlock(x + 0, y + 16, z + 0, Blocks.air);
		world.setBlock(x + 0, y + 16, z + 1, Blocks.air);
		world.setBlock(x + 0, y + 16, z + 2, Blocks.air);
		world.setBlock(x + 0, y + 16, z + 3, Blocks.air);
		world.setBlock(x + 0, y + 16, z + 4, Blocks.air);
		world.setBlock(x + 0, y + 16, z + 5, Blocks.air);
		world.setBlock(x + 0, y + 16, z + 6, Blocks.air);
		world.setBlock(x + 0, y + 16, z + 7, Blocks.air);
		world.setBlock(x + 0, y + 16, z + 8, Blocks.air);
		world.setBlock(x + 0, y + 16, z + 9, Blocks.air);
		world.setBlock(x + 0, y + 16, z + 10, Blocks.air);
		world.setBlock(x + 0, y + 16, z + 11, Blocks.air);
		world.setBlock(x + 0, y + 16, z + 12, Blocks.air);
		world.setBlock(x + 0, y + 16, z + 13, Blocks.air);
		world.setBlock(x + 0, y + 16, z + 14, Blocks.air);
		world.setBlock(x + 0, y + 16, z + 15, Blocks.air);
		world.setBlock(x + 0, y + 16, z + 16, Blocks.sandstone);
		world.setBlock(x + 0, y + 16, z + 17, Blocks.sandstone, 2, 2);
		world.setBlock(x + 0, y + 16, z + 18, Blocks.wool, 14, 2);
		world.setBlock(x + 0, y + 16, z + 19, Blocks.sandstone, 2, 2);
		world.setBlock(x + 0, y + 16, z + 20, Blocks.sandstone);
		world.setBlock(x + 0, y + 17, z + 0, Blocks.air);
		world.setBlock(x + 0, y + 17, z + 1, Blocks.air);
		world.setBlock(x + 0, y + 17, z + 2, Blocks.air);
		world.setBlock(x + 0, y + 17, z + 3, Blocks.air);
		world.setBlock(x + 0, y + 17, z + 4, Blocks.air);
		world.setBlock(x + 0, y + 17, z + 5, Blocks.air);
		world.setBlock(x + 0, y + 17, z + 6, Blocks.air);
		world.setBlock(x + 0, y + 17, z + 7, Blocks.air);
		world.setBlock(x + 0, y + 17, z + 8, Blocks.air);
		world.setBlock(x + 0, y + 17, z + 9, Blocks.air);
		world.setBlock(x + 0, y + 17, z + 10, Blocks.air);
		world.setBlock(x + 0, y + 17, z + 11, Blocks.air);
		world.setBlock(x + 0, y + 17, z + 12, Blocks.air);
		world.setBlock(x + 0, y + 17, z + 13, Blocks.air);
		world.setBlock(x + 0, y + 17, z + 14, Blocks.air);
		world.setBlock(x + 0, y + 17, z + 15, Blocks.air);
		world.setBlock(x + 0, y + 17, z + 16, Blocks.sandstone);
		world.setBlock(x + 0, y + 17, z + 17, Blocks.wool, 14, 2);
		world.setBlock(x + 0, y + 17, z + 18, Blocks.sandstone, 1, 2);
		world.setBlock(x + 0, y + 17, z + 19, Blocks.wool, 14, 2);
		world.setBlock(x + 0, y + 17, z + 20, Blocks.sandstone);
		world.setBlock(x + 0, y + 18, z + 0, Blocks.air);
		world.setBlock(x + 0, y + 18, z + 1, Blocks.air);
		world.setBlock(x + 0, y + 18, z + 2, Blocks.air);
		world.setBlock(x + 0, y + 18, z + 3, Blocks.air);
		world.setBlock(x + 0, y + 18, z + 4, Blocks.air);
		world.setBlock(x + 0, y + 18, z + 5, Blocks.air);
		world.setBlock(x + 0, y + 18, z + 6, Blocks.air);
		world.setBlock(x + 0, y + 18, z + 7, Blocks.air);
		world.setBlock(x + 0, y + 18, z + 8, Blocks.air);
		world.setBlock(x + 0, y + 18, z + 9, Blocks.air);
		world.setBlock(x + 0, y + 18, z + 10, Blocks.air);
		world.setBlock(x + 0, y + 18, z + 11, Blocks.air);
		world.setBlock(x + 0, y + 18, z + 12, Blocks.air);
		world.setBlock(x + 0, y + 18, z + 13, Blocks.air);
		world.setBlock(x + 0, y + 18, z + 14, Blocks.air);
		world.setBlock(x + 0, y + 18, z + 15, Blocks.air);
		world.setBlock(x + 0, y + 18, z + 16, Blocks.sandstone);
		world.setBlock(x + 0, y + 18, z + 17, Blocks.sandstone, 2, 2);
		world.setBlock(x + 0, y + 18, z + 18, Blocks.wool, 14, 2);
		world.setBlock(x + 0, y + 18, z + 19, Blocks.sandstone, 2, 2);
		world.setBlock(x + 0, y + 18, z + 20, Blocks.sandstone);
		world.setBlock(x + 0, y + 19, z + 0, Blocks.air);
		world.setBlock(x + 0, y + 19, z + 1, Blocks.air);
		world.setBlock(x + 0, y + 19, z + 2, Blocks.air);
		world.setBlock(x + 0, y + 19, z + 3, Blocks.air);
		world.setBlock(x + 0, y + 19, z + 4, Blocks.air);
		world.setBlock(x + 0, y + 19, z + 5, Blocks.air);
		world.setBlock(x + 0, y + 19, z + 6, Blocks.air);
		world.setBlock(x + 0, y + 19, z + 7, Blocks.air);
		world.setBlock(x + 0, y + 19, z + 8, Blocks.air);
		world.setBlock(x + 0, y + 19, z + 9, Blocks.air);
		world.setBlock(x + 0, y + 19, z + 10, Blocks.air);
		world.setBlock(x + 0, y + 19, z + 11, Blocks.air);
		world.setBlock(x + 0, y + 19, z + 12, Blocks.air);
		world.setBlock(x + 0, y + 19, z + 13, Blocks.air);
		world.setBlock(x + 0, y + 19, z + 14, Blocks.air);
		world.setBlock(x + 0, y + 19, z + 15, Blocks.air);
		world.setBlock(x + 0, y + 19, z + 16, Blocks.sandstone);
		world.setBlock(x + 0, y + 19, z + 17, Blocks.wool, 14, 2);
		world.setBlock(x + 0, y + 19, z + 18, Blocks.sandstone, 1, 2);
		world.setBlock(x + 0, y + 19, z + 19, Blocks.wool, 14, 2);
		world.setBlock(x + 0, y + 19, z + 20, Blocks.sandstone);
		world.setBlock(x + 0, y + 20, z + 0, Blocks.air);
		world.setBlock(x + 0, y + 20, z + 1, Blocks.air);
		world.setBlock(x + 0, y + 20, z + 2, Blocks.air);
		world.setBlock(x + 0, y + 20, z + 3, Blocks.air);
		world.setBlock(x + 0, y + 20, z + 4, Blocks.air);
		world.setBlock(x + 0, y + 20, z + 5, Blocks.air);
		world.setBlock(x + 0, y + 20, z + 6, Blocks.air);
		world.setBlock(x + 0, y + 20, z + 7, Blocks.air);
		world.setBlock(x + 0, y + 20, z + 8, Blocks.air);
		world.setBlock(x + 0, y + 20, z + 9, Blocks.air);
		world.setBlock(x + 0, y + 20, z + 10, Blocks.air);
		world.setBlock(x + 0, y + 20, z + 11, Blocks.air);
		world.setBlock(x + 0, y + 20, z + 12, Blocks.air);
		world.setBlock(x + 0, y + 20, z + 13, Blocks.air);
		world.setBlock(x + 0, y + 20, z + 14, Blocks.air);
		world.setBlock(x + 0, y + 20, z + 15, Blocks.air);
		world.setBlock(x + 0, y + 20, z + 16, Blocks.sandstone);
		world.setBlock(x + 0, y + 20, z + 17, Blocks.wool, 14, 2);
		world.setBlock(x + 0, y + 20, z + 18, Blocks.wool, 14, 2);
		world.setBlock(x + 0, y + 20, z + 19, Blocks.wool, 14, 2);
		world.setBlock(x + 0, y + 20, z + 20, Blocks.sandstone);
		world.setBlock(x + 0, y + 21, z + 0, Blocks.air);
		world.setBlock(x + 0, y + 21, z + 1, Blocks.air);
		world.setBlock(x + 0, y + 21, z + 2, Blocks.air);
		world.setBlock(x + 0, y + 21, z + 3, Blocks.air);
		world.setBlock(x + 0, y + 21, z + 4, Blocks.air);
		world.setBlock(x + 0, y + 21, z + 5, Blocks.air);
		world.setBlock(x + 0, y + 21, z + 6, Blocks.air);
		world.setBlock(x + 0, y + 21, z + 7, Blocks.air);
		world.setBlock(x + 0, y + 21, z + 8, Blocks.air);
		world.setBlock(x + 0, y + 21, z + 9, Blocks.air);
		world.setBlock(x + 0, y + 21, z + 10, Blocks.air);
		world.setBlock(x + 0, y + 21, z + 11, Blocks.air);
		world.setBlock(x + 0, y + 21, z + 12, Blocks.air);
		world.setBlock(x + 0, y + 21, z + 13, Blocks.air);
		world.setBlock(x + 0, y + 21, z + 14, Blocks.air);
		world.setBlock(x + 0, y + 21, z + 15, Blocks.air);
		world.setBlock(x + 0, y + 21, z + 16, Blocks.sandstone);
		world.setBlock(x + 0, y + 21, z + 17, Blocks.sandstone, 2, 2);
		world.setBlock(x + 0, y + 21, z + 18, Blocks.sandstone, 2, 2);
		world.setBlock(x + 0, y + 21, z + 19, Blocks.sandstone, 2, 2);
		world.setBlock(x + 0, y + 21, z + 20, Blocks.sandstone);
		world.setBlock(x + 0, y + 22, z + 0, Blocks.air);
		world.setBlock(x + 0, y + 22, z + 1, Blocks.air);
		world.setBlock(x + 0, y + 22, z + 2, Blocks.air);
		world.setBlock(x + 0, y + 22, z + 3, Blocks.air);
		world.setBlock(x + 0, y + 22, z + 4, Blocks.air);
		world.setBlock(x + 0, y + 22, z + 5, Blocks.air);
		world.setBlock(x + 0, y + 22, z + 6, Blocks.air);
		world.setBlock(x + 0, y + 22, z + 7, Blocks.air);
		world.setBlock(x + 0, y + 22, z + 8, Blocks.air);
		world.setBlock(x + 0, y + 22, z + 9, Blocks.air);
		world.setBlock(x + 0, y + 22, z + 10, Blocks.air);
		world.setBlock(x + 0, y + 22, z + 11, Blocks.air);
		world.setBlock(x + 0, y + 22, z + 12, Blocks.air);
		world.setBlock(x + 0, y + 22, z + 13, Blocks.air);
		world.setBlock(x + 0, y + 22, z + 14, Blocks.air);
		world.setBlock(x + 0, y + 22, z + 15, Blocks.air);
		world.setBlock(x + 0, y + 22, z + 16, Blocks.sandstone);
		world.setBlock(x + 0, y + 22, z + 17, Blocks.sandstone);
		world.setBlock(x + 0, y + 22, z + 18, Blocks.sandstone);
		world.setBlock(x + 0, y + 22, z + 19, Blocks.sandstone);
		world.setBlock(x + 0, y + 22, z + 20, Blocks.sandstone);
		world.setBlock(x + 0, y + 23, z + 0, Blocks.air);
		world.setBlock(x + 0, y + 23, z + 1, Blocks.air);
		world.setBlock(x + 0, y + 23, z + 2, Blocks.air);
		world.setBlock(x + 0, y + 23, z + 3, Blocks.air);
		world.setBlock(x + 0, y + 23, z + 4, Blocks.air);
		world.setBlock(x + 0, y + 23, z + 5, Blocks.air);
		world.setBlock(x + 0, y + 23, z + 6, Blocks.air);
		world.setBlock(x + 0, y + 23, z + 7, Blocks.air);
		world.setBlock(x + 0, y + 23, z + 8, Blocks.air);
		world.setBlock(x + 0, y + 23, z + 9, Blocks.air);
		world.setBlock(x + 0, y + 23, z + 10, Blocks.air);
		world.setBlock(x + 0, y + 23, z + 11, Blocks.air);
		world.setBlock(x + 0, y + 23, z + 12, Blocks.air);
		world.setBlock(x + 0, y + 23, z + 13, Blocks.air);
		world.setBlock(x + 0, y + 23, z + 14, Blocks.air);
		world.setBlock(x + 0, y + 23, z + 15, Blocks.air);
		world.setBlock(x + 0, y + 23, z + 16, Blocks.air);
		world.setBlock(x + 0, y + 23, z + 17, Blocks.air);
		world.setBlock(x + 0, y + 23, z + 18, Blocks.sandstone_stairs);
		world.setBlock(x + 0, y + 23, z + 19, Blocks.air);
		world.setBlock(x + 0, y + 23, z + 20, Blocks.air);
		world.setBlock(x + 1, y + 0, z + 0, Blocks.sandstone);
		world.setBlock(x + 1, y + 0, z + 1, Blocks.sandstone);
		world.setBlock(x + 1, y + 0, z + 2, Blocks.sandstone);
		world.setBlock(x + 1, y + 0, z + 3, Blocks.sandstone);
		world.setBlock(x + 1, y + 0, z + 4, Blocks.sandstone);
		world.setBlock(x + 1, y + 0, z + 5, Blocks.sandstone);
		world.setBlock(x + 1, y + 0, z + 6, Blocks.sandstone);
		world.setBlock(x + 1, y + 0, z + 7, Blocks.sandstone);
		world.setBlock(x + 1, y + 0, z + 8, Blocks.sandstone);
		world.setBlock(x + 1, y + 0, z + 9, Blocks.sandstone);
		world.setBlock(x + 1, y + 0, z + 10, Blocks.sandstone);
		world.setBlock(x + 1, y + 0, z + 11, Blocks.sandstone);
		world.setBlock(x + 1, y + 0, z + 12, Blocks.sandstone);
		world.setBlock(x + 1, y + 0, z + 13, Blocks.sandstone);
		world.setBlock(x + 1, y + 0, z + 14, Blocks.sandstone);
		world.setBlock(x + 1, y + 0, z + 15, Blocks.sandstone);
		world.setBlock(x + 1, y + 0, z + 16, Blocks.sandstone);
		world.setBlock(x + 1, y + 0, z + 17, Blocks.sandstone);
		world.setBlock(x + 1, y + 0, z + 18, Blocks.sandstone);
		world.setBlock(x + 1, y + 0, z + 19, Blocks.sandstone);
		world.setBlock(x + 1, y + 0, z + 20, Blocks.sandstone);
		world.setBlock(x + 1, y + 1, z + 0, Blocks.sandstone);
		world.setBlock(x + 1, y + 1, z + 1, Blocks.sandstone);
		world.setBlock(x + 1, y + 1, z + 2, Blocks.sandstone);
		world.setBlock(x + 1, y + 1, z + 3, Blocks.sandstone);
		world.setBlock(x + 1, y + 1, z + 4, Blocks.sandstone);
		world.setBlock(x + 1, y + 1, z + 5, Blocks.sandstone);
		world.setBlock(x + 1, y + 1, z + 6, Blocks.sandstone);
		world.setBlock(x + 1, y + 1, z + 7, Blocks.sandstone);
		world.setBlock(x + 1, y + 1, z + 8, Blocks.sandstone);
		world.setBlock(x + 1, y + 1, z + 9, Blocks.sandstone);
		world.setBlock(x + 1, y + 1, z + 10, Blocks.sandstone);
		world.setBlock(x + 1, y + 1, z + 11, Blocks.sandstone);
		world.setBlock(x + 1, y + 1, z + 12, Blocks.sandstone);
		world.setBlock(x + 1, y + 1, z + 13, Blocks.sandstone);
		world.setBlock(x + 1, y + 1, z + 14, Blocks.sandstone);
		world.setBlock(x + 1, y + 1, z + 15, Blocks.sandstone);
		world.setBlock(x + 1, y + 1, z + 16, Blocks.sandstone);
		world.setBlock(x + 1, y + 1, z + 17, Blocks.sandstone);
		world.setBlock(x + 1, y + 1, z + 18, Blocks.sandstone);
		world.setBlock(x + 1, y + 1, z + 19, Blocks.sandstone);
		world.setBlock(x + 1, y + 1, z + 20, Blocks.sandstone);
		world.setBlock(x + 1, y + 2, z + 0, Blocks.sandstone);
		world.setBlock(x + 1, y + 2, z + 1, Blocks.sandstone);
		world.setBlock(x + 1, y + 2, z + 2, Blocks.sandstone);
		world.setBlock(x + 1, y + 2, z + 3, Blocks.sandstone);
		world.setBlock(x + 1, y + 2, z + 4, Blocks.sandstone);
		world.setBlock(x + 1, y + 2, z + 5, Blocks.sandstone);
		world.setBlock(x + 1, y + 2, z + 6, Blocks.sandstone);
		world.setBlock(x + 1, y + 2, z + 7, Blocks.sandstone);
		world.setBlock(x + 1, y + 2, z + 8, Blocks.sandstone);
		world.setBlock(x + 1, y + 2, z + 9, Blocks.sandstone);
		world.setBlock(x + 1, y + 2, z + 10, Blocks.sandstone);
		world.setBlock(x + 1, y + 2, z + 11, Blocks.sandstone);
		world.setBlock(x + 1, y + 2, z + 12, Blocks.sandstone);
		world.setBlock(x + 1, y + 2, z + 13, Blocks.sandstone);
		world.setBlock(x + 1, y + 2, z + 14, Blocks.sandstone);
		world.setBlock(x + 1, y + 2, z + 15, Blocks.sandstone);
		world.setBlock(x + 1, y + 2, z + 16, Blocks.sandstone);
		world.setBlock(x + 1, y + 2, z + 17, Blocks.sandstone);
		world.setBlock(x + 1, y + 2, z + 18, Blocks.sandstone);
		world.setBlock(x + 1, y + 2, z + 19, Blocks.sandstone);
		world.setBlock(x + 1, y + 2, z + 20, Blocks.sandstone);
		world.setBlock(x + 1, y + 3, z + 0, Blocks.sandstone);
		world.setBlock(x + 1, y + 3, z + 1, Blocks.sandstone);
		world.setBlock(x + 1, y + 3, z + 2, Blocks.sandstone);
		world.setBlock(x + 1, y + 3, z + 3, Blocks.sandstone);
		world.setBlock(x + 1, y + 3, z + 4, Blocks.sandstone);
		world.setBlock(x + 1, y + 3, z + 5, Blocks.sandstone);
		world.setBlock(x + 1, y + 3, z + 6, Blocks.sandstone);
		world.setBlock(x + 1, y + 3, z + 7, Blocks.sandstone);
		world.setBlock(x + 1, y + 3, z + 8, Blocks.sandstone);
		world.setBlock(x + 1, y + 3, z + 9, Blocks.sandstone);
		world.setBlock(x + 1, y + 3, z + 10, Blocks.sandstone);
		world.setBlock(x + 1, y + 3, z + 11, Blocks.sandstone);
		world.setBlock(x + 1, y + 3, z + 12, Blocks.sandstone);
		world.setBlock(x + 1, y + 3, z + 13, Blocks.sandstone);
		world.setBlock(x + 1, y + 3, z + 14, Blocks.sandstone);
		world.setBlock(x + 1, y + 3, z + 15, Blocks.sandstone);
		world.setBlock(x + 1, y + 3, z + 16, Blocks.sandstone);
		world.setBlock(x + 1, y + 3, z + 17, Blocks.sandstone);
		world.setBlock(x + 1, y + 3, z + 18, Blocks.sandstone);
		world.setBlock(x + 1, y + 3, z + 19, Blocks.sandstone);
		world.setBlock(x + 1, y + 3, z + 20, Blocks.sandstone);
		world.setBlock(x + 1, y + 4, z + 0, Blocks.sandstone);
		world.setBlock(x + 1, y + 4, z + 1, Blocks.sandstone);
		world.setBlock(x + 1, y + 4, z + 2, Blocks.sandstone);
		world.setBlock(x + 1, y + 4, z + 3, Blocks.sandstone);
		world.setBlock(x + 1, y + 4, z + 4, Blocks.sandstone);
		world.setBlock(x + 1, y + 4, z + 5, Blocks.sandstone);
		world.setBlock(x + 1, y + 4, z + 6, Blocks.sandstone);
		world.setBlock(x + 1, y + 4, z + 7, Blocks.sandstone);
		world.setBlock(x + 1, y + 4, z + 8, Blocks.sandstone);
		world.setBlock(x + 1, y + 4, z + 9, Blocks.sandstone);
		world.setBlock(x + 1, y + 4, z + 10, Blocks.sandstone);
		world.setBlock(x + 1, y + 4, z + 11, Blocks.sandstone);
		world.setBlock(x + 1, y + 4, z + 12, Blocks.sandstone);
		world.setBlock(x + 1, y + 4, z + 13, Blocks.sandstone);
		world.setBlock(x + 1, y + 4, z + 14, Blocks.sandstone);
		world.setBlock(x + 1, y + 4, z + 15, Blocks.sandstone);
		world.setBlock(x + 1, y + 4, z + 16, Blocks.sandstone);
		world.setBlock(x + 1, y + 4, z + 17, Blocks.sandstone);
		world.setBlock(x + 1, y + 4, z + 18, Blocks.sandstone);
		world.setBlock(x + 1, y + 4, z + 19, Blocks.sandstone);
		world.setBlock(x + 1, y + 4, z + 20, Blocks.sandstone);
		world.setBlock(x + 1, y + 5, z + 0, Blocks.sandstone);
		world.setBlock(x + 1, y + 5, z + 1, Blocks.sandstone);
		world.setBlock(x + 1, y + 5, z + 2, Blocks.sandstone);
		world.setBlock(x + 1, y + 5, z + 3, Blocks.sandstone);
		world.setBlock(x + 1, y + 5, z + 4, Blocks.sandstone);
		world.setBlock(x + 1, y + 5, z + 5, Blocks.sandstone);
		world.setBlock(x + 1, y + 5, z + 6, Blocks.sandstone);
		world.setBlock(x + 1, y + 5, z + 7, Blocks.sandstone);
		world.setBlock(x + 1, y + 5, z + 8, Blocks.sandstone);
		world.setBlock(x + 1, y + 5, z + 9, Blocks.sandstone);
		world.setBlock(x + 1, y + 5, z + 10, Blocks.sandstone);
		world.setBlock(x + 1, y + 5, z + 11, Blocks.sandstone);
		world.setBlock(x + 1, y + 5, z + 12, Blocks.sandstone);
		world.setBlock(x + 1, y + 5, z + 13, Blocks.sandstone);
		world.setBlock(x + 1, y + 5, z + 14, Blocks.sandstone);
		world.setBlock(x + 1, y + 5, z + 15, Blocks.sandstone);
		world.setBlock(x + 1, y + 5, z + 16, Blocks.sandstone);
		world.setBlock(x + 1, y + 5, z + 17, Blocks.sandstone);
		world.setBlock(x + 1, y + 5, z + 18, Blocks.sandstone);
		world.setBlock(x + 1, y + 5, z + 19, Blocks.sandstone);
		world.setBlock(x + 1, y + 5, z + 20, Blocks.sandstone);
		world.setBlock(x + 1, y + 6, z + 0, Blocks.sandstone);
		world.setBlock(x + 1, y + 6, z + 1, Blocks.sandstone);
		world.setBlock(x + 1, y + 6, z + 2, Blocks.sandstone);
		world.setBlock(x + 1, y + 6, z + 3, Blocks.sandstone);
		world.setBlock(x + 1, y + 6, z + 4, Blocks.sandstone);
		world.setBlock(x + 1, y + 6, z + 5, Blocks.sandstone);
		world.setBlock(x + 1, y + 6, z + 6, Blocks.sandstone);
		world.setBlock(x + 1, y + 6, z + 7, Blocks.sandstone);
		world.setBlock(x + 1, y + 6, z + 8, Blocks.sandstone);
		world.setBlock(x + 1, y + 6, z + 9, Blocks.sandstone);
		world.setBlock(x + 1, y + 6, z + 10, Blocks.sandstone);
		world.setBlock(x + 1, y + 6, z + 11, Blocks.sandstone);
		world.setBlock(x + 1, y + 6, z + 12, Blocks.sandstone);
		world.setBlock(x + 1, y + 6, z + 13, Blocks.sandstone);
		world.setBlock(x + 1, y + 6, z + 14, Blocks.sandstone);
		world.setBlock(x + 1, y + 6, z + 15, Blocks.sandstone);
		world.setBlock(x + 1, y + 6, z + 16, Blocks.sandstone);
		world.setBlock(x + 1, y + 6, z + 17, Blocks.sandstone);
		world.setBlock(x + 1, y + 6, z + 18, Blocks.sandstone);
		world.setBlock(x + 1, y + 6, z + 19, Blocks.sandstone);
		world.setBlock(x + 1, y + 6, z + 20, Blocks.sandstone);
		world.setBlock(x + 1, y + 7, z + 0, Blocks.sandstone);
		world.setBlock(x + 1, y + 7, z + 1, Blocks.sandstone);
		world.setBlock(x + 1, y + 7, z + 2, Blocks.sandstone);
		world.setBlock(x + 1, y + 7, z + 3, Blocks.sandstone);
		world.setBlock(x + 1, y + 7, z + 4, Blocks.sandstone);
		world.setBlock(x + 1, y + 7, z + 5, Blocks.sandstone);
		world.setBlock(x + 1, y + 7, z + 6, Blocks.sandstone);
		world.setBlock(x + 1, y + 7, z + 7, Blocks.sandstone);
		world.setBlock(x + 1, y + 7, z + 8, Blocks.sandstone);
		world.setBlock(x + 1, y + 7, z + 9, Blocks.sandstone);
		world.setBlock(x + 1, y + 7, z + 10, Blocks.sandstone);
		world.setBlock(x + 1, y + 7, z + 11, Blocks.sandstone);
		world.setBlock(x + 1, y + 7, z + 12, Blocks.sandstone);
		world.setBlock(x + 1, y + 7, z + 13, Blocks.sandstone);
		world.setBlock(x + 1, y + 7, z + 14, Blocks.sandstone);
		world.setBlock(x + 1, y + 7, z + 15, Blocks.sandstone);
		world.setBlock(x + 1, y + 7, z + 16, Blocks.sandstone);
		world.setBlock(x + 1, y + 7, z + 17, Blocks.sandstone);
		world.setBlock(x + 1, y + 7, z + 18, Blocks.sandstone);
		world.setBlock(x + 1, y + 7, z + 19, Blocks.sandstone);
		world.setBlock(x + 1, y + 7, z + 20, Blocks.sandstone);
		world.setBlock(x + 1, y + 8, z + 0, Blocks.sandstone);
		world.setBlock(x + 1, y + 8, z + 1, Blocks.sandstone);
		world.setBlock(x + 1, y + 8, z + 2, Blocks.sandstone);
		world.setBlock(x + 1, y + 8, z + 3, Blocks.sandstone);
		world.setBlock(x + 1, y + 8, z + 4, Blocks.sandstone);
		world.setBlock(x + 1, y + 8, z + 5, Blocks.sandstone);
		world.setBlock(x + 1, y + 8, z + 6, Blocks.sandstone);
		world.setBlock(x + 1, y + 8, z + 7, Blocks.sandstone);
		world.setBlock(x + 1, y + 8, z + 8, Blocks.sandstone);
		world.setBlock(x + 1, y + 8, z + 9, Blocks.sandstone);
		world.setBlock(x + 1, y + 8, z + 10, Blocks.sandstone);
		world.setBlock(x + 1, y + 8, z + 11, Blocks.sandstone);
		world.setBlock(x + 1, y + 8, z + 12, Blocks.sandstone);
		world.setBlock(x + 1, y + 8, z + 13, Blocks.sandstone);
		world.setBlock(x + 1, y + 8, z + 14, Blocks.sandstone);
		world.setBlock(x + 1, y + 8, z + 15, Blocks.sandstone);
		world.setBlock(x + 1, y + 8, z + 16, Blocks.sandstone);
		world.setBlock(x + 1, y + 8, z + 17, Blocks.sandstone);
		world.setBlock(x + 1, y + 8, z + 18, Blocks.sandstone);
		world.setBlock(x + 1, y + 8, z + 19, Blocks.sandstone);
		world.setBlock(x + 1, y + 8, z + 20, Blocks.sandstone);
		world.setBlock(x + 1, y + 9, z + 0, Blocks.sandstone);
		world.setBlock(x + 1, y + 9, z + 1, Blocks.sandstone);
		world.setBlock(x + 1, y + 9, z + 2, Blocks.sandstone);
		world.setBlock(x + 1, y + 9, z + 3, Blocks.sandstone);
		world.setBlock(x + 1, y + 9, z + 4, Blocks.sandstone);
		world.setBlock(x + 1, y + 9, z + 5, Blocks.sandstone);
		world.setBlock(x + 1, y + 9, z + 6, Blocks.sandstone);
		world.setBlock(x + 1, y + 9, z + 7, Blocks.sandstone);
		world.setBlock(x + 1, y + 9, z + 8, Blocks.sandstone);
		world.setBlock(x + 1, y + 9, z + 9, Blocks.sandstone);
		world.setBlock(x + 1, y + 9, z + 10, Blocks.sandstone);
		world.setBlock(x + 1, y + 9, z + 11, Blocks.sandstone);
		world.setBlock(x + 1, y + 9, z + 12, Blocks.sandstone);
		world.setBlock(x + 1, y + 9, z + 13, Blocks.sandstone);
		world.setBlock(x + 1, y + 9, z + 14, Blocks.sandstone);
		world.setBlock(x + 1, y + 9, z + 15, Blocks.sandstone);
		world.setBlock(x + 1, y + 9, z + 16, Blocks.sandstone);
		world.setBlock(x + 1, y + 9, z + 17, Blocks.sandstone);
		world.setBlock(x + 1, y + 9, z + 18, Blocks.sandstone);
		world.setBlock(x + 1, y + 9, z + 19, Blocks.sandstone);
		world.setBlock(x + 1, y + 9, z + 20, Blocks.sandstone);
		world.setBlock(x + 1, y + 10, z + 0, Blocks.sandstone);
		world.setBlock(x + 1, y + 10, z + 1, Blocks.sandstone);
		world.setBlock(x + 1, y + 10, z + 2, Blocks.sandstone);
		world.setBlock(x + 1, y + 10, z + 3, Blocks.sandstone);
		world.setBlock(x + 1, y + 10, z + 4, Blocks.sandstone);
		world.setBlock(x + 1, y + 10, z + 5, Blocks.sandstone);
		world.setBlock(x + 1, y + 10, z + 6, Blocks.sandstone);
		world.setBlock(x + 1, y + 10, z + 7, Blocks.sandstone);
		world.setBlock(x + 1, y + 10, z + 8, Blocks.sandstone);
		world.setBlock(x + 1, y + 10, z + 9, Blocks.sandstone);
		world.setBlock(x + 1, y + 10, z + 10, Blocks.sandstone);
		world.setBlock(x + 1, y + 10, z + 11, Blocks.sandstone);
		world.setBlock(x + 1, y + 10, z + 12, Blocks.sandstone);
		world.setBlock(x + 1, y + 10, z + 13, Blocks.sandstone);
		world.setBlock(x + 1, y + 10, z + 14, Blocks.sandstone);
		world.setBlock(x + 1, y + 10, z + 15, Blocks.sandstone);
		world.setBlock(x + 1, y + 10, z + 16, Blocks.sandstone);
		world.setBlock(x + 1, y + 10, z + 17, Blocks.sandstone);
		world.setBlock(x + 1, y + 10, z + 18, Blocks.sandstone);
		world.setBlock(x + 1, y + 10, z + 19, Blocks.sandstone);
		world.setBlock(x + 1, y + 10, z + 20, Blocks.sandstone);
		world.setBlock(x + 1, y + 11, z + 0, Blocks.sandstone);
		world.setBlock(x + 1, y + 11, z + 1, Blocks.sandstone);
		world.setBlock(x + 1, y + 11, z + 2, Blocks.sandstone);
		world.setBlock(x + 1, y + 11, z + 3, Blocks.sandstone);
		world.setBlock(x + 1, y + 11, z + 4, Blocks.sandstone);
		world.setBlock(x + 1, y + 11, z + 5, Blocks.sandstone);
		world.setBlock(x + 1, y + 11, z + 6, Blocks.sandstone);
		world.setBlock(x + 1, y + 11, z + 7, Blocks.sandstone);
		world.setBlock(x + 1, y + 11, z + 8, Blocks.sandstone);
		world.setBlock(x + 1, y + 11, z + 9, Blocks.sandstone);
		world.setBlock(x + 1, y + 11, z + 10, Blocks.sandstone);
		world.setBlock(x + 1, y + 11, z + 11, Blocks.sandstone);
		world.setBlock(x + 1, y + 11, z + 12, Blocks.sandstone);
		world.setBlock(x + 1, y + 11, z + 13, Blocks.sandstone);
		world.setBlock(x + 1, y + 11, z + 14, Blocks.sandstone);
		world.setBlock(x + 1, y + 11, z + 15, Blocks.sandstone);
		world.setBlock(x + 1, y + 11, z + 16, Blocks.sandstone);
		world.setBlock(x + 1, y + 11, z + 17, Blocks.sandstone);
		world.setBlock(x + 1, y + 11, z + 18, Blocks.sandstone);
		world.setBlock(x + 1, y + 11, z + 19, Blocks.sandstone);
		world.setBlock(x + 1, y + 11, z + 20, Blocks.sandstone);
		world.setBlock(x + 1, y + 12, z + 0, Blocks.sandstone);
		world.setBlock(x + 1, y + 12, z + 1, Blocks.sandstone);
		world.setBlock(x + 1, y + 12, z + 2, Blocks.sandstone);
		world.setBlock(x + 1, y + 12, z + 3, Blocks.sandstone);
		world.setBlock(x + 1, y + 12, z + 4, Blocks.sandstone);
		world.setBlock(x + 1, y + 12, z + 5, Blocks.sandstone);
		world.setBlock(x + 1, y + 12, z + 6, Blocks.sandstone);
		world.setBlock(x + 1, y + 12, z + 7, Blocks.sandstone);
		world.setBlock(x + 1, y + 12, z + 8, Blocks.sandstone);
		world.setBlock(x + 1, y + 12, z + 9, Blocks.sandstone);
		world.setBlock(x + 1, y + 12, z + 10, Blocks.sandstone);
		world.setBlock(x + 1, y + 12, z + 11, Blocks.sandstone);
		world.setBlock(x + 1, y + 12, z + 12, Blocks.sandstone);
		world.setBlock(x + 1, y + 12, z + 13, Blocks.sandstone);
		world.setBlock(x + 1, y + 12, z + 14, Blocks.sandstone);
		world.setBlock(x + 1, y + 12, z + 15, Blocks.sandstone);
		world.setBlock(x + 1, y + 12, z + 16, Blocks.sandstone);
		world.setBlock(x + 1, y + 12, z + 17, Blocks.sandstone);
		world.setBlock(x + 1, y + 12, z + 18, Blocks.sandstone);
		world.setBlock(x + 1, y + 12, z + 19, Blocks.sandstone);
		world.setBlock(x + 1, y + 12, z + 20, Blocks.sandstone);
		world.setBlock(x + 1, y + 13, z + 0, Blocks.sandstone);
		world.setBlock(x + 1, y + 13, z + 1, Blocks.sandstone);
		world.setBlock(x + 1, y + 13, z + 2, Blocks.sandstone);
		world.setBlock(x + 1, y + 13, z + 3, Blocks.sandstone);
		world.setBlock(x + 1, y + 13, z + 4, Blocks.sandstone);
		world.setBlock(x + 1, y + 13, z + 5, Blocks.sandstone);
		world.setBlock(x + 1, y + 13, z + 6, Blocks.sandstone);
		world.setBlock(x + 1, y + 13, z + 7, Blocks.sandstone);
		world.setBlock(x + 1, y + 13, z + 8, Blocks.sandstone);
		world.setBlock(x + 1, y + 13, z + 9, Blocks.sandstone);
		world.setBlock(x + 1, y + 13, z + 10, Blocks.sandstone);
		world.setBlock(x + 1, y + 13, z + 11, Blocks.sandstone);
		world.setBlock(x + 1, y + 13, z + 12, Blocks.sandstone);
		world.setBlock(x + 1, y + 13, z + 13, Blocks.sandstone);
		world.setBlock(x + 1, y + 13, z + 14, Blocks.sandstone);
		world.setBlock(x + 1, y + 13, z + 15, Blocks.sandstone);
		world.setBlock(x + 1, y + 13, z + 16, Blocks.sandstone);
		world.setBlock(x + 1, y + 13, z + 17, Blocks.sandstone);
		world.setBlock(x + 1, y + 13, z + 18, Blocks.sandstone);
		world.setBlock(x + 1, y + 13, z + 19, Blocks.sandstone);
		world.setBlock(x + 1, y + 13, z + 20, Blocks.sandstone);
		world.setBlock(x + 1, y + 14, z + 0, Blocks.air);
		world.setBlock(x + 1, y + 14, z + 1, Blocks.sandstone);
		world.setBlock(x + 1, y + 14, z + 2, Blocks.sandstone);
		world.setBlock(x + 1, y + 14, z + 3, Blocks.sandstone);
		world.setBlock(x + 1, y + 14, z + 4, Blocks.sandstone);
		world.setBlock(x + 1, y + 14, z + 5, Blocks.sandstone);
		world.setBlock(x + 1, y + 14, z + 6, Blocks.sandstone);
		world.setBlock(x + 1, y + 14, z + 7, Blocks.sandstone);
		world.setBlock(x + 1, y + 14, z + 8, Blocks.sandstone);
		world.setBlock(x + 1, y + 14, z + 9, Blocks.sandstone);
		world.setBlock(x + 1, y + 14, z + 10, Blocks.sandstone);
		world.setBlock(x + 1, y + 14, z + 11, Blocks.sandstone);
		world.setBlock(x + 1, y + 14, z + 12, Blocks.sandstone);
		world.setBlock(x + 1, y + 14, z + 13, Blocks.sandstone);
		world.setBlock(x + 1, y + 14, z + 14, Blocks.sandstone);
		world.setBlock(x + 1, y + 14, z + 15, Blocks.sandstone);
		world.setBlock(x + 1, y + 14, z + 16, Blocks.sandstone);
		world.setBlock(x + 1, y + 14, z + 17, Blocks.mob_spawner);
		TileEntityMobSpawner spawner1 = (TileEntityMobSpawner)world.getTileEntity(x + 1, y + 14, z + 17);
		spawner1.func_145881_a().setEntityName("Skeleton");
		world.setBlock(x + 1, y + 14, z + 18, Blocks.air);
		world.setBlock(x + 1, y + 14, z + 19, Blocks.chest, 5, 3);
		TileEntityChest tileentitychest = (TileEntityChest)world.getTileEntity(x + 1, y + 14, z + 19);
        if (tileentitychest != null)
        {
            ChestGenHooks info = ChestGenHooks.getInfo(ChestGenHooks.DUNGEON_CHEST);
            WeightedRandomChestContent.generateChestContents(rand, info.getItems(rand), tileentitychest, info.getCount(rand));
        }
		world.setBlock(x + 1, y + 14, z + 20, Blocks.sandstone);
		world.setBlock(x + 1, y + 15, z + 0, Blocks.air);
		world.setBlock(x + 1, y + 15, z + 1, Blocks.air);
		world.setBlock(x + 1, y + 15, z + 2, Blocks.air);
		world.setBlock(x + 1, y + 15, z + 3, Blocks.air);
		world.setBlock(x + 1, y + 15, z + 4, Blocks.air);
		world.setBlock(x + 1, y + 15, z + 5, Blocks.air);
		world.setBlock(x + 1, y + 15, z + 6, Blocks.air);
		world.setBlock(x + 1, y + 15, z + 7, Blocks.air);
		world.setBlock(x + 1, y + 15, z + 8, Blocks.air);
		world.setBlock(x + 1, y + 15, z + 9, Blocks.air);
		world.setBlock(x + 1, y + 15, z + 10, Blocks.air);
		world.setBlock(x + 1, y + 15, z + 11, Blocks.air);
		world.setBlock(x + 1, y + 15, z + 12, Blocks.air);
		world.setBlock(x + 1, y + 15, z + 13, Blocks.air);
		world.setBlock(x + 1, y + 15, z + 14, Blocks.air);
		world.setBlock(x + 1, y + 15, z + 15, Blocks.air);
		world.setBlock(x + 1, y + 15, z + 16, Blocks.sandstone);
		world.setBlock(x + 1, y + 15, z + 17, Blocks.air);
		world.setBlock(x + 1, y + 15, z + 18, Blocks.air);
		world.setBlock(x + 1, y + 15, z + 19, Blocks.air);
		world.setBlock(x + 1, y + 15, z + 20, Blocks.sandstone, 2, 2);
		world.setBlock(x + 1, y + 16, z + 0, Blocks.air);
		world.setBlock(x + 1, y + 16, z + 1, Blocks.air);
		world.setBlock(x + 1, y + 16, z + 2, Blocks.air);
		world.setBlock(x + 1, y + 16, z + 3, Blocks.air);
		world.setBlock(x + 1, y + 16, z + 4, Blocks.air);
		world.setBlock(x + 1, y + 16, z + 5, Blocks.air);
		world.setBlock(x + 1, y + 16, z + 6, Blocks.air);
		world.setBlock(x + 1, y + 16, z + 7, Blocks.air);
		world.setBlock(x + 1, y + 16, z + 8, Blocks.air);
		world.setBlock(x + 1, y + 16, z + 9, Blocks.air);
		world.setBlock(x + 1, y + 16, z + 10, Blocks.air);
		world.setBlock(x + 1, y + 16, z + 11, Blocks.air);
		world.setBlock(x + 1, y + 16, z + 12, Blocks.air);
		world.setBlock(x + 1, y + 16, z + 13, Blocks.air);
		world.setBlock(x + 1, y + 16, z + 14, Blocks.air);
		world.setBlock(x + 1, y + 16, z + 15, Blocks.air);
		world.setBlock(x + 1, y + 16, z + 16, Blocks.sandstone);
		world.setBlock(x + 1, y + 16, z + 17, Blocks.air);
		world.setBlock(x + 1, y + 16, z + 18, Blocks.air);
		world.setBlock(x + 1, y + 16, z + 19, Blocks.air);
		world.setBlock(x + 1, y + 16, z + 20, Blocks.sandstone, 2, 2);
		world.setBlock(x + 1, y + 17, z + 0, Blocks.air);
		world.setBlock(x + 1, y + 17, z + 1, Blocks.air);
		world.setBlock(x + 1, y + 17, z + 2, Blocks.air);
		world.setBlock(x + 1, y + 17, z + 3, Blocks.air);
		world.setBlock(x + 1, y + 17, z + 4, Blocks.air);
		world.setBlock(x + 1, y + 17, z + 5, Blocks.air);
		world.setBlock(x + 1, y + 17, z + 6, Blocks.air);
		world.setBlock(x + 1, y + 17, z + 7, Blocks.air);
		world.setBlock(x + 1, y + 17, z + 8, Blocks.air);
		world.setBlock(x + 1, y + 17, z + 9, Blocks.air);
		world.setBlock(x + 1, y + 17, z + 10, Blocks.air);
		world.setBlock(x + 1, y + 17, z + 11, Blocks.air);
		world.setBlock(x + 1, y + 17, z + 12, Blocks.air);
		world.setBlock(x + 1, y + 17, z + 13, Blocks.air);
		world.setBlock(x + 1, y + 17, z + 14, Blocks.air);
		world.setBlock(x + 1, y + 17, z + 15, Blocks.air);
		world.setBlock(x + 1, y + 17, z + 16, Blocks.sandstone);
		world.setBlock(x + 1, y + 17, z + 17, Blocks.air);
		world.setBlock(x + 1, y + 17, z + 18, Blocks.air);
		world.setBlock(x + 1, y + 17, z + 19, Blocks.air);
		world.setBlock(x + 1, y + 17, z + 20, Blocks.wool, 14, 2);
		world.setBlock(x + 1, y + 18, z + 0, Blocks.air);
		world.setBlock(x + 1, y + 18, z + 1, Blocks.air);
		world.setBlock(x + 1, y + 18, z + 2, Blocks.air);
		world.setBlock(x + 1, y + 18, z + 3, Blocks.air);
		world.setBlock(x + 1, y + 18, z + 4, Blocks.air);
		world.setBlock(x + 1, y + 18, z + 5, Blocks.air);
		world.setBlock(x + 1, y + 18, z + 6, Blocks.air);
		world.setBlock(x + 1, y + 18, z + 7, Blocks.air);
		world.setBlock(x + 1, y + 18, z + 8, Blocks.air);
		world.setBlock(x + 1, y + 18, z + 9, Blocks.air);
		world.setBlock(x + 1, y + 18, z + 10, Blocks.air);
		world.setBlock(x + 1, y + 18, z + 11, Blocks.air);
		world.setBlock(x + 1, y + 18, z + 12, Blocks.air);
		world.setBlock(x + 1, y + 18, z + 13, Blocks.air);
		world.setBlock(x + 1, y + 18, z + 14, Blocks.air);
		world.setBlock(x + 1, y + 18, z + 15, Blocks.air);
		world.setBlock(x + 1, y + 18, z + 16, Blocks.sandstone);
		world.setBlock(x + 1, y + 18, z + 17, Blocks.air);
		world.setBlock(x + 1, y + 18, z + 18, Blocks.air);
		world.setBlock(x + 1, y + 18, z + 19, Blocks.air);
		world.setBlock(x + 1, y + 18, z + 20, Blocks.sandstone, 2, 2);
		world.setBlock(x + 1, y + 19, z + 0, Blocks.air);
		world.setBlock(x + 1, y + 19, z + 1, Blocks.air);
		world.setBlock(x + 1, y + 19, z + 2, Blocks.air);
		world.setBlock(x + 1, y + 19, z + 3, Blocks.air);
		world.setBlock(x + 1, y + 19, z + 4, Blocks.air);
		world.setBlock(x + 1, y + 19, z + 5, Blocks.air);
		world.setBlock(x + 1, y + 19, z + 6, Blocks.air);
		world.setBlock(x + 1, y + 19, z + 7, Blocks.air);
		world.setBlock(x + 1, y + 19, z + 8, Blocks.air);
		world.setBlock(x + 1, y + 19, z + 9, Blocks.air);
		world.setBlock(x + 1, y + 19, z + 10, Blocks.air);
		world.setBlock(x + 1, y + 19, z + 11, Blocks.air);
		world.setBlock(x + 1, y + 19, z + 12, Blocks.air);
		world.setBlock(x + 1, y + 19, z + 13, Blocks.air);
		world.setBlock(x + 1, y + 19, z + 14, Blocks.air);
		world.setBlock(x + 1, y + 19, z + 15, Blocks.air);
		world.setBlock(x + 1, y + 19, z + 16, Blocks.sandstone);
		world.setBlock(x + 1, y + 19, z + 17, Blocks.air);
		world.setBlock(x + 1, y + 19, z + 18, Blocks.air);
		world.setBlock(x + 1, y + 19, z + 19, Blocks.air);
		world.setBlock(x + 1, y + 19, z + 20, Blocks.wool, 14, 2);
		world.setBlock(x + 1, y + 20, z + 0, Blocks.air);
		world.setBlock(x + 1, y + 20, z + 1, Blocks.air);
		world.setBlock(x + 1, y + 20, z + 2, Blocks.air);
		world.setBlock(x + 1, y + 20, z + 3, Blocks.air);
		world.setBlock(x + 1, y + 20, z + 4, Blocks.air);
		world.setBlock(x + 1, y + 20, z + 5, Blocks.air);
		world.setBlock(x + 1, y + 20, z + 6, Blocks.air);
		world.setBlock(x + 1, y + 20, z + 7, Blocks.air);
		world.setBlock(x + 1, y + 20, z + 8, Blocks.air);
		world.setBlock(x + 1, y + 20, z + 9, Blocks.air);
		world.setBlock(x + 1, y + 20, z + 10, Blocks.air);
		world.setBlock(x + 1, y + 20, z + 11, Blocks.air);
		world.setBlock(x + 1, y + 20, z + 12, Blocks.air);
		world.setBlock(x + 1, y + 20, z + 13, Blocks.air);
		world.setBlock(x + 1, y + 20, z + 14, Blocks.air);
		world.setBlock(x + 1, y + 20, z + 15, Blocks.air);
		world.setBlock(x + 1, y + 20, z + 16, Blocks.sandstone);
		world.setBlock(x + 1, y + 20, z + 17, Blocks.air);
		world.setBlock(x + 1, y + 20, z + 18, Blocks.air);
		world.setBlock(x + 1, y + 20, z + 19, Blocks.air);
		world.setBlock(x + 1, y + 20, z + 20, Blocks.wool, 14, 2);
		world.setBlock(x + 1, y + 21, z + 0, Blocks.air);
		world.setBlock(x + 1, y + 21, z + 1, Blocks.air);
		world.setBlock(x + 1, y + 21, z + 2, Blocks.air);
		world.setBlock(x + 1, y + 21, z + 3, Blocks.air);
		world.setBlock(x + 1, y + 21, z + 4, Blocks.air);
		world.setBlock(x + 1, y + 21, z + 5, Blocks.air);
		world.setBlock(x + 1, y + 21, z + 6, Blocks.air);
		world.setBlock(x + 1, y + 21, z + 7, Blocks.air);
		world.setBlock(x + 1, y + 21, z + 8, Blocks.air);
		world.setBlock(x + 1, y + 21, z + 9, Blocks.air);
		world.setBlock(x + 1, y + 21, z + 10, Blocks.air);
		world.setBlock(x + 1, y + 21, z + 11, Blocks.air);
		world.setBlock(x + 1, y + 21, z + 12, Blocks.air);
		world.setBlock(x + 1, y + 21, z + 13, Blocks.air);
		world.setBlock(x + 1, y + 21, z + 14, Blocks.air);
		world.setBlock(x + 1, y + 21, z + 15, Blocks.air);
		world.setBlock(x + 1, y + 21, z + 16, Blocks.sandstone);
		world.setBlock(x + 1, y + 21, z + 17, Blocks.air);
		world.setBlock(x + 1, y + 21, z + 18, Blocks.air);
		world.setBlock(x + 1, y + 21, z + 19, Blocks.air);
		world.setBlock(x + 1, y + 21, z + 20, Blocks.sandstone, 2, 2);
		world.setBlock(x + 1, y + 22, z + 0, Blocks.air);
		world.setBlock(x + 1, y + 22, z + 1, Blocks.air);
		world.setBlock(x + 1, y + 22, z + 2, Blocks.air);
		world.setBlock(x + 1, y + 22, z + 3, Blocks.air);
		world.setBlock(x + 1, y + 22, z + 4, Blocks.air);
		world.setBlock(x + 1, y + 22, z + 5, Blocks.air);
		world.setBlock(x + 1, y + 22, z + 6, Blocks.air);
		world.setBlock(x + 1, y + 22, z + 7, Blocks.air);
		world.setBlock(x + 1, y + 22, z + 8, Blocks.air);
		world.setBlock(x + 1, y + 22, z + 9, Blocks.air);
		world.setBlock(x + 1, y + 22, z + 10, Blocks.air);
		world.setBlock(x + 1, y + 22, z + 11, Blocks.air);
		world.setBlock(x + 1, y + 22, z + 12, Blocks.air);
		world.setBlock(x + 1, y + 22, z + 13, Blocks.air);
		world.setBlock(x + 1, y + 22, z + 14, Blocks.air);
		world.setBlock(x + 1, y + 22, z + 15, Blocks.air);
		world.setBlock(x + 1, y + 22, z + 16, Blocks.sandstone);
		world.setBlock(x + 1, y + 22, z + 17, Blocks.sandstone);
		world.setBlock(x + 1, y + 22, z + 18, Blocks.sandstone);
		world.setBlock(x + 1, y + 22, z + 19, Blocks.sandstone);
		world.setBlock(x + 1, y + 22, z + 20, Blocks.sandstone);
		world.setBlock(x + 1, y + 23, z + 0, Blocks.air);
		world.setBlock(x + 1, y + 23, z + 1, Blocks.air);
		world.setBlock(x + 1, y + 23, z + 2, Blocks.air);
		world.setBlock(x + 1, y + 23, z + 3, Blocks.air);
		world.setBlock(x + 1, y + 23, z + 4, Blocks.air);
		world.setBlock(x + 1, y + 23, z + 5, Blocks.air);
		world.setBlock(x + 1, y + 23, z + 6, Blocks.air);
		world.setBlock(x + 1, y + 23, z + 7, Blocks.air);
		world.setBlock(x + 1, y + 23, z + 8, Blocks.air);
		world.setBlock(x + 1, y + 23, z + 9, Blocks.air);
		world.setBlock(x + 1, y + 23, z + 10, Blocks.air);
		world.setBlock(x + 1, y + 23, z + 11, Blocks.air);
		world.setBlock(x + 1, y + 23, z + 12, Blocks.air);
		world.setBlock(x + 1, y + 23, z + 13, Blocks.air);
		world.setBlock(x + 1, y + 23, z + 14, Blocks.air);
		world.setBlock(x + 1, y + 23, z + 15, Blocks.air);
		world.setBlock(x + 1, y + 23, z + 16, Blocks.air);
		world.setBlock(x + 1, y + 23, z + 17, Blocks.sandstone);
		world.setBlock(x + 1, y + 23, z + 18, Blocks.sandstone);
		world.setBlock(x + 1, y + 23, z + 19, Blocks.sandstone);
		world.setBlock(x + 1, y + 23, z + 20, Blocks.air);
		world.setBlock(x + 2, y + 0, z + 0, Blocks.sandstone);
		world.setBlock(x + 2, y + 0, z + 1, Blocks.sandstone);
		world.setBlock(x + 2, y + 0, z + 2, Blocks.sandstone);
		world.setBlock(x + 2, y + 0, z + 3, Blocks.sandstone);
		world.setBlock(x + 2, y + 0, z + 4, Blocks.sandstone);
		world.setBlock(x + 2, y + 0, z + 5, Blocks.sandstone);
		world.setBlock(x + 2, y + 0, z + 6, Blocks.sandstone);
		world.setBlock(x + 2, y + 0, z + 7, Blocks.sandstone);
		world.setBlock(x + 2, y + 0, z + 8, Blocks.sandstone);
		world.setBlock(x + 2, y + 0, z + 9, Blocks.sandstone);
		world.setBlock(x + 2, y + 0, z + 10, Blocks.sandstone);
		world.setBlock(x + 2, y + 0, z + 11, Blocks.sandstone);
		world.setBlock(x + 2, y + 0, z + 12, Blocks.sandstone);
		world.setBlock(x + 2, y + 0, z + 13, Blocks.sandstone);
		world.setBlock(x + 2, y + 0, z + 14, Blocks.sandstone);
		world.setBlock(x + 2, y + 0, z + 15, Blocks.sandstone);
		world.setBlock(x + 2, y + 0, z + 16, Blocks.sandstone);
		world.setBlock(x + 2, y + 0, z + 17, Blocks.sandstone);
		world.setBlock(x + 2, y + 0, z + 18, Blocks.sandstone);
		world.setBlock(x + 2, y + 0, z + 19, Blocks.sandstone);
		world.setBlock(x + 2, y + 0, z + 20, Blocks.sandstone);
		world.setBlock(x + 2, y + 1, z + 0, Blocks.sandstone);
		world.setBlock(x + 2, y + 1, z + 1, Blocks.sandstone);
		world.setBlock(x + 2, y + 1, z + 2, Blocks.sandstone);
		world.setBlock(x + 2, y + 1, z + 3, Blocks.sandstone);
		world.setBlock(x + 2, y + 1, z + 4, Blocks.sandstone);
		world.setBlock(x + 2, y + 1, z + 5, Blocks.sandstone);
		world.setBlock(x + 2, y + 1, z + 6, Blocks.sandstone);
		world.setBlock(x + 2, y + 1, z + 7, Blocks.sandstone);
		world.setBlock(x + 2, y + 1, z + 8, Blocks.sandstone);
		world.setBlock(x + 2, y + 1, z + 9, Blocks.sandstone);
		world.setBlock(x + 2, y + 1, z + 10, Blocks.sandstone);
		world.setBlock(x + 2, y + 1, z + 11, Blocks.sandstone);
		world.setBlock(x + 2, y + 1, z + 12, Blocks.sandstone);
		world.setBlock(x + 2, y + 1, z + 13, Blocks.sandstone);
		world.setBlock(x + 2, y + 1, z + 14, Blocks.sandstone);
		world.setBlock(x + 2, y + 1, z + 15, Blocks.sandstone);
		world.setBlock(x + 2, y + 1, z + 16, Blocks.sandstone);
		world.setBlock(x + 2, y + 1, z + 17, Blocks.sandstone);
		world.setBlock(x + 2, y + 1, z + 18, Blocks.sandstone);
		world.setBlock(x + 2, y + 1, z + 19, Blocks.sandstone);
		world.setBlock(x + 2, y + 1, z + 20, Blocks.sandstone);
		world.setBlock(x + 2, y + 2, z + 0, Blocks.sandstone);
		world.setBlock(x + 2, y + 2, z + 1, Blocks.sandstone);
		world.setBlock(x + 2, y + 2, z + 2, Blocks.sandstone);
		world.setBlock(x + 2, y + 2, z + 3, Blocks.sandstone);
		world.setBlock(x + 2, y + 2, z + 4, Blocks.sandstone);
		world.setBlock(x + 2, y + 2, z + 5, Blocks.sandstone);
		world.setBlock(x + 2, y + 2, z + 6, Blocks.sandstone);
		world.setBlock(x + 2, y + 2, z + 7, Blocks.sandstone);
		world.setBlock(x + 2, y + 2, z + 8, Blocks.sandstone);
		world.setBlock(x + 2, y + 2, z + 9, Blocks.sandstone);
		world.setBlock(x + 2, y + 2, z + 10, Blocks.sandstone);
		world.setBlock(x + 2, y + 2, z + 11, Blocks.sandstone);
		world.setBlock(x + 2, y + 2, z + 12, Blocks.sandstone);
		world.setBlock(x + 2, y + 2, z + 13, Blocks.sandstone);
		world.setBlock(x + 2, y + 2, z + 14, Blocks.sandstone);
		world.setBlock(x + 2, y + 2, z + 15, Blocks.sandstone);
		world.setBlock(x + 2, y + 2, z + 16, Blocks.sandstone);
		world.setBlock(x + 2, y + 2, z + 17, Blocks.sandstone);
		world.setBlock(x + 2, y + 2, z + 18, Blocks.sandstone);
		world.setBlock(x + 2, y + 2, z + 19, Blocks.sandstone);
		world.setBlock(x + 2, y + 2, z + 20, Blocks.sandstone);
		world.setBlock(x + 2, y + 3, z + 0, Blocks.sandstone);
		world.setBlock(x + 2, y + 3, z + 1, Blocks.sandstone);
		world.setBlock(x + 2, y + 3, z + 2, Blocks.sandstone);
		world.setBlock(x + 2, y + 3, z + 3, Blocks.sandstone);
		world.setBlock(x + 2, y + 3, z + 4, Blocks.sandstone);
		world.setBlock(x + 2, y + 3, z + 5, Blocks.sandstone);
		world.setBlock(x + 2, y + 3, z + 6, Blocks.sandstone);
		world.setBlock(x + 2, y + 3, z + 7, Blocks.sandstone);
		world.setBlock(x + 2, y + 3, z + 8, Blocks.sandstone);
		world.setBlock(x + 2, y + 3, z + 9, Blocks.sandstone);
		world.setBlock(x + 2, y + 3, z + 10, Blocks.sandstone);
		world.setBlock(x + 2, y + 3, z + 11, Blocks.sandstone);
		world.setBlock(x + 2, y + 3, z + 12, Blocks.sandstone);
		world.setBlock(x + 2, y + 3, z + 13, Blocks.sandstone);
		world.setBlock(x + 2, y + 3, z + 14, Blocks.sandstone);
		world.setBlock(x + 2, y + 3, z + 15, Blocks.sandstone);
		world.setBlock(x + 2, y + 3, z + 16, Blocks.sandstone);
		world.setBlock(x + 2, y + 3, z + 17, Blocks.sandstone);
		world.setBlock(x + 2, y + 3, z + 18, Blocks.sandstone);
		world.setBlock(x + 2, y + 3, z + 19, Blocks.sandstone);
		world.setBlock(x + 2, y + 3, z + 20, Blocks.sandstone);
		world.setBlock(x + 2, y + 4, z + 0, Blocks.sandstone);
		world.setBlock(x + 2, y + 4, z + 1, Blocks.sandstone);
		world.setBlock(x + 2, y + 4, z + 2, Blocks.sandstone);
		world.setBlock(x + 2, y + 4, z + 3, Blocks.sandstone);
		world.setBlock(x + 2, y + 4, z + 4, Blocks.sandstone);
		world.setBlock(x + 2, y + 4, z + 5, Blocks.sandstone);
		world.setBlock(x + 2, y + 4, z + 6, Blocks.sandstone);
		world.setBlock(x + 2, y + 4, z + 7, Blocks.sandstone);
		world.setBlock(x + 2, y + 4, z + 8, Blocks.sandstone);
		world.setBlock(x + 2, y + 4, z + 9, Blocks.sandstone);
		world.setBlock(x + 2, y + 4, z + 10, Blocks.sandstone);
		world.setBlock(x + 2, y + 4, z + 11, Blocks.sandstone);
		world.setBlock(x + 2, y + 4, z + 12, Blocks.sandstone);
		world.setBlock(x + 2, y + 4, z + 13, Blocks.sandstone);
		world.setBlock(x + 2, y + 4, z + 14, Blocks.sandstone);
		world.setBlock(x + 2, y + 4, z + 15, Blocks.sandstone);
		world.setBlock(x + 2, y + 4, z + 16, Blocks.sandstone);
		world.setBlock(x + 2, y + 4, z + 17, Blocks.sandstone);
		world.setBlock(x + 2, y + 4, z + 18, Blocks.sandstone);
		world.setBlock(x + 2, y + 4, z + 19, Blocks.sandstone);
		world.setBlock(x + 2, y + 4, z + 20, Blocks.sandstone);
		world.setBlock(x + 2, y + 5, z + 0, Blocks.sandstone);
		world.setBlock(x + 2, y + 5, z + 1, Blocks.sandstone);
		world.setBlock(x + 2, y + 5, z + 2, Blocks.sandstone);
		world.setBlock(x + 2, y + 5, z + 3, Blocks.sandstone);
		world.setBlock(x + 2, y + 5, z + 4, Blocks.sandstone);
		world.setBlock(x + 2, y + 5, z + 5, Blocks.sandstone);
		world.setBlock(x + 2, y + 5, z + 6, Blocks.sandstone);
		world.setBlock(x + 2, y + 5, z + 7, Blocks.sandstone);
		world.setBlock(x + 2, y + 5, z + 8, Blocks.sandstone);
		world.setBlock(x + 2, y + 5, z + 9, Blocks.sandstone);
		world.setBlock(x + 2, y + 5, z + 10, Blocks.sandstone);
		world.setBlock(x + 2, y + 5, z + 11, Blocks.sandstone);
		world.setBlock(x + 2, y + 5, z + 12, Blocks.sandstone);
		world.setBlock(x + 2, y + 5, z + 13, Blocks.sandstone);
		world.setBlock(x + 2, y + 5, z + 14, Blocks.sandstone);
		world.setBlock(x + 2, y + 5, z + 15, Blocks.sandstone);
		world.setBlock(x + 2, y + 5, z + 16, Blocks.sandstone);
		world.setBlock(x + 2, y + 5, z + 17, Blocks.sandstone);
		world.setBlock(x + 2, y + 5, z + 18, Blocks.sandstone);
		world.setBlock(x + 2, y + 5, z + 19, Blocks.sandstone);
		world.setBlock(x + 2, y + 5, z + 20, Blocks.sandstone);
		world.setBlock(x + 2, y + 6, z + 0, Blocks.sandstone);
		world.setBlock(x + 2, y + 6, z + 1, Blocks.sandstone);
		world.setBlock(x + 2, y + 6, z + 2, Blocks.sandstone);
		world.setBlock(x + 2, y + 6, z + 3, Blocks.sandstone);
		world.setBlock(x + 2, y + 6, z + 4, Blocks.sandstone);
		world.setBlock(x + 2, y + 6, z + 5, Blocks.sandstone);
		world.setBlock(x + 2, y + 6, z + 6, Blocks.sandstone);
		world.setBlock(x + 2, y + 6, z + 7, Blocks.sandstone);
		world.setBlock(x + 2, y + 6, z + 8, Blocks.sandstone);
		world.setBlock(x + 2, y + 6, z + 9, Blocks.sandstone);
		world.setBlock(x + 2, y + 6, z + 10, Blocks.sandstone);
		world.setBlock(x + 2, y + 6, z + 11, Blocks.sandstone);
		world.setBlock(x + 2, y + 6, z + 12, Blocks.sandstone);
		world.setBlock(x + 2, y + 6, z + 13, Blocks.sandstone);
		world.setBlock(x + 2, y + 6, z + 14, Blocks.sandstone);
		world.setBlock(x + 2, y + 6, z + 15, Blocks.sandstone);
		world.setBlock(x + 2, y + 6, z + 16, Blocks.sandstone);
		world.setBlock(x + 2, y + 6, z + 17, Blocks.sandstone);
		world.setBlock(x + 2, y + 6, z + 18, Blocks.sandstone);
		world.setBlock(x + 2, y + 6, z + 19, Blocks.sandstone);
		world.setBlock(x + 2, y + 6, z + 20, Blocks.sandstone);
		world.setBlock(x + 2, y + 7, z + 0, Blocks.sandstone);
		world.setBlock(x + 2, y + 7, z + 1, Blocks.sandstone);
		world.setBlock(x + 2, y + 7, z + 2, Blocks.sandstone);
		world.setBlock(x + 2, y + 7, z + 3, Blocks.sandstone);
		world.setBlock(x + 2, y + 7, z + 4, Blocks.sandstone);
		world.setBlock(x + 2, y + 7, z + 5, Blocks.sandstone);
		world.setBlock(x + 2, y + 7, z + 6, Blocks.sandstone);
		world.setBlock(x + 2, y + 7, z + 7, Blocks.sandstone);
		world.setBlock(x + 2, y + 7, z + 8, Blocks.sandstone);
		world.setBlock(x + 2, y + 7, z + 9, Blocks.sandstone);
		world.setBlock(x + 2, y + 7, z + 10, Blocks.sandstone);
		world.setBlock(x + 2, y + 7, z + 11, Blocks.sandstone);
		world.setBlock(x + 2, y + 7, z + 12, Blocks.sandstone);
		world.setBlock(x + 2, y + 7, z + 13, Blocks.sandstone);
		world.setBlock(x + 2, y + 7, z + 14, Blocks.sandstone);
		world.setBlock(x + 2, y + 7, z + 15, Blocks.sandstone);
		world.setBlock(x + 2, y + 7, z + 16, Blocks.sandstone);
		world.setBlock(x + 2, y + 7, z + 17, Blocks.sandstone);
		world.setBlock(x + 2, y + 7, z + 18, Blocks.sandstone);
		world.setBlock(x + 2, y + 7, z + 19, Blocks.sandstone);
		world.setBlock(x + 2, y + 7, z + 20, Blocks.sandstone);
		world.setBlock(x + 2, y + 8, z + 0, Blocks.sandstone);
		world.setBlock(x + 2, y + 8, z + 1, Blocks.sandstone);
		world.setBlock(x + 2, y + 8, z + 2, Blocks.sandstone);
		world.setBlock(x + 2, y + 8, z + 3, Blocks.sandstone);
		world.setBlock(x + 2, y + 8, z + 4, Blocks.sandstone);
		world.setBlock(x + 2, y + 8, z + 5, Blocks.sandstone);
		world.setBlock(x + 2, y + 8, z + 6, Blocks.sandstone);
		world.setBlock(x + 2, y + 8, z + 7, Blocks.sandstone);
		world.setBlock(x + 2, y + 8, z + 8, Blocks.sandstone);
		world.setBlock(x + 2, y + 8, z + 9, Blocks.sandstone);
		world.setBlock(x + 2, y + 8, z + 10, Blocks.sandstone);
		world.setBlock(x + 2, y + 8, z + 11, Blocks.sandstone);
		world.setBlock(x + 2, y + 8, z + 12, Blocks.sandstone);
		world.setBlock(x + 2, y + 8, z + 13, Blocks.sandstone);
		world.setBlock(x + 2, y + 8, z + 14, Blocks.sandstone);
		world.setBlock(x + 2, y + 8, z + 15, Blocks.sandstone);
		world.setBlock(x + 2, y + 8, z + 16, Blocks.sandstone);
		world.setBlock(x + 2, y + 8, z + 17, Blocks.sandstone);
		world.setBlock(x + 2, y + 8, z + 18, Blocks.sandstone);
		world.setBlock(x + 2, y + 8, z + 19, Blocks.sandstone);
		world.setBlock(x + 2, y + 8, z + 20, Blocks.sandstone);
		world.setBlock(x + 2, y + 9, z + 0, Blocks.sandstone);
		world.setBlock(x + 2, y + 9, z + 1, Blocks.sandstone);
		world.setBlock(x + 2, y + 9, z + 2, Blocks.sandstone);
		world.setBlock(x + 2, y + 9, z + 3, Blocks.sandstone);
		world.setBlock(x + 2, y + 9, z + 4, Blocks.sandstone);
		world.setBlock(x + 2, y + 9, z + 5, Blocks.sandstone);
		world.setBlock(x + 2, y + 9, z + 6, Blocks.sandstone);
		world.setBlock(x + 2, y + 9, z + 7, Blocks.sandstone);
		world.setBlock(x + 2, y + 9, z + 8, Blocks.sandstone);
		world.setBlock(x + 2, y + 9, z + 9, Blocks.sandstone);
		world.setBlock(x + 2, y + 9, z + 10, Blocks.sandstone);
		world.setBlock(x + 2, y + 9, z + 11, Blocks.sandstone);
		world.setBlock(x + 2, y + 9, z + 12, Blocks.sandstone);
		world.setBlock(x + 2, y + 9, z + 13, Blocks.sandstone);
		world.setBlock(x + 2, y + 9, z + 14, Blocks.sandstone);
		world.setBlock(x + 2, y + 9, z + 15, Blocks.sandstone);
		world.setBlock(x + 2, y + 9, z + 16, Blocks.sandstone);
		world.setBlock(x + 2, y + 9, z + 17, Blocks.sandstone);
		world.setBlock(x + 2, y + 9, z + 18, Blocks.sandstone);
		world.setBlock(x + 2, y + 9, z + 19, Blocks.sandstone);
		world.setBlock(x + 2, y + 9, z + 20, Blocks.sandstone);
		world.setBlock(x + 2, y + 10, z + 0, Blocks.sandstone);
		world.setBlock(x + 2, y + 10, z + 1, Blocks.sandstone);
		world.setBlock(x + 2, y + 10, z + 2, Blocks.sandstone);
		world.setBlock(x + 2, y + 10, z + 3, Blocks.sandstone);
		world.setBlock(x + 2, y + 10, z + 4, Blocks.sandstone);
		world.setBlock(x + 2, y + 10, z + 5, Blocks.sandstone);
		world.setBlock(x + 2, y + 10, z + 6, Blocks.sandstone);
		world.setBlock(x + 2, y + 10, z + 7, Blocks.sandstone);
		world.setBlock(x + 2, y + 10, z + 8, Blocks.sandstone);
		world.setBlock(x + 2, y + 10, z + 9, Blocks.sandstone);
		world.setBlock(x + 2, y + 10, z + 10, Blocks.sandstone);
		world.setBlock(x + 2, y + 10, z + 11, Blocks.sandstone);
		world.setBlock(x + 2, y + 10, z + 12, Blocks.sandstone);
		world.setBlock(x + 2, y + 10, z + 13, Blocks.sandstone);
		world.setBlock(x + 2, y + 10, z + 14, Blocks.sandstone);
		world.setBlock(x + 2, y + 10, z + 15, Blocks.sandstone);
		world.setBlock(x + 2, y + 10, z + 16, Blocks.sandstone);
		world.setBlock(x + 2, y + 10, z + 17, Blocks.sandstone);
		world.setBlock(x + 2, y + 10, z + 18, Blocks.sandstone);
		world.setBlock(x + 2, y + 10, z + 19, Blocks.sandstone);
		world.setBlock(x + 2, y + 10, z + 20, Blocks.sandstone);
		world.setBlock(x + 2, y + 11, z + 0, Blocks.sandstone);
		world.setBlock(x + 2, y + 11, z + 1, Blocks.sandstone);
		world.setBlock(x + 2, y + 11, z + 2, Blocks.sandstone);
		world.setBlock(x + 2, y + 11, z + 3, Blocks.sandstone);
		world.setBlock(x + 2, y + 11, z + 4, Blocks.sandstone);
		world.setBlock(x + 2, y + 11, z + 5, Blocks.sandstone);
		world.setBlock(x + 2, y + 11, z + 6, Blocks.sandstone);
		world.setBlock(x + 2, y + 11, z + 7, Blocks.sandstone);
		world.setBlock(x + 2, y + 11, z + 8, Blocks.sandstone);
		world.setBlock(x + 2, y + 11, z + 9, Blocks.sandstone);
		world.setBlock(x + 2, y + 11, z + 10, Blocks.sandstone);
		world.setBlock(x + 2, y + 11, z + 11, Blocks.sandstone);
		world.setBlock(x + 2, y + 11, z + 12, Blocks.sandstone);
		world.setBlock(x + 2, y + 11, z + 13, Blocks.sandstone);
		world.setBlock(x + 2, y + 11, z + 14, Blocks.sandstone);
		world.setBlock(x + 2, y + 11, z + 15, Blocks.sandstone);
		world.setBlock(x + 2, y + 11, z + 16, Blocks.sandstone);
		world.setBlock(x + 2, y + 11, z + 17, Blocks.sandstone);
		world.setBlock(x + 2, y + 11, z + 18, Blocks.sandstone);
		world.setBlock(x + 2, y + 11, z + 19, Blocks.sandstone);
		world.setBlock(x + 2, y + 11, z + 20, Blocks.sandstone);
		world.setBlock(x + 2, y + 12, z + 0, Blocks.sandstone);
		world.setBlock(x + 2, y + 12, z + 1, Blocks.sandstone);
		world.setBlock(x + 2, y + 12, z + 2, Blocks.sandstone);
		world.setBlock(x + 2, y + 12, z + 3, Blocks.sandstone);
		world.setBlock(x + 2, y + 12, z + 4, Blocks.sandstone);
		world.setBlock(x + 2, y + 12, z + 5, Blocks.sandstone);
		world.setBlock(x + 2, y + 12, z + 6, Blocks.sandstone);
		world.setBlock(x + 2, y + 12, z + 7, Blocks.sandstone);
		world.setBlock(x + 2, y + 12, z + 8, Blocks.sandstone);
		world.setBlock(x + 2, y + 12, z + 9, Blocks.sandstone);
		world.setBlock(x + 2, y + 12, z + 10, Blocks.sandstone);
		world.setBlock(x + 2, y + 12, z + 11, Blocks.sandstone);
		world.setBlock(x + 2, y + 12, z + 12, Blocks.sandstone);
		world.setBlock(x + 2, y + 12, z + 13, Blocks.sandstone);
		world.setBlock(x + 2, y + 12, z + 14, Blocks.sandstone);
		world.setBlock(x + 2, y + 12, z + 15, Blocks.sandstone);
		world.setBlock(x + 2, y + 12, z + 16, Blocks.sandstone);
		world.setBlock(x + 2, y + 12, z + 17, Blocks.sandstone);
		world.setBlock(x + 2, y + 12, z + 18, Blocks.sandstone);
		world.setBlock(x + 2, y + 12, z + 19, Blocks.sandstone);
		world.setBlock(x + 2, y + 12, z + 20, Blocks.sandstone);
		world.setBlock(x + 2, y + 13, z + 0, Blocks.sandstone);
		world.setBlock(x + 2, y + 13, z + 1, Blocks.sandstone);
		world.setBlock(x + 2, y + 13, z + 2, Blocks.sandstone);
		world.setBlock(x + 2, y + 13, z + 3, Blocks.sandstone);
		world.setBlock(x + 2, y + 13, z + 4, Blocks.sandstone);
		world.setBlock(x + 2, y + 13, z + 5, Blocks.sandstone);
		world.setBlock(x + 2, y + 13, z + 6, Blocks.sandstone);
		world.setBlock(x + 2, y + 13, z + 7, Blocks.sandstone);
		world.setBlock(x + 2, y + 13, z + 8, Blocks.sandstone);
		world.setBlock(x + 2, y + 13, z + 9, Blocks.sandstone);
		world.setBlock(x + 2, y + 13, z + 10, Blocks.sandstone);
		world.setBlock(x + 2, y + 13, z + 11, Blocks.sandstone);
		world.setBlock(x + 2, y + 13, z + 12, Blocks.sandstone);
		world.setBlock(x + 2, y + 13, z + 13, Blocks.sandstone);
		world.setBlock(x + 2, y + 13, z + 14, Blocks.sandstone);
		world.setBlock(x + 2, y + 13, z + 15, Blocks.sandstone);
		world.setBlock(x + 2, y + 13, z + 16, Blocks.sandstone);
		world.setBlock(x + 2, y + 13, z + 17, Blocks.sandstone);
		world.setBlock(x + 2, y + 13, z + 18, Blocks.sandstone);
		world.setBlock(x + 2, y + 13, z + 19, Blocks.sandstone);
		world.setBlock(x + 2, y + 13, z + 20, Blocks.sandstone);
		world.setBlock(x + 2, y + 14, z + 0, Blocks.air);
		world.setBlock(x + 2, y + 14, z + 1, Blocks.sandstone);
		world.setBlock(x + 2, y + 14, z + 2, Blocks.air);
		world.setBlock(x + 2, y + 14, z + 3, Blocks.air);
		world.setBlock(x + 2, y + 14, z + 4, Blocks.air);
		world.setBlock(x + 2, y + 14, z + 5, Blocks.air);
		world.setBlock(x + 2, y + 14, z + 6, Blocks.air);
		world.setBlock(x + 2, y + 14, z + 7, Blocks.air);
		world.setBlock(x + 2, y + 14, z + 8, Blocks.air);
		world.setBlock(x + 2, y + 14, z + 9, Blocks.air);
		world.setBlock(x + 2, y + 14, z + 10, Blocks.air);
		world.setBlock(x + 2, y + 14, z + 11, Blocks.air);
		world.setBlock(x + 2, y + 14, z + 12, Blocks.air);
		world.setBlock(x + 2, y + 14, z + 13, Blocks.air);
		world.setBlock(x + 2, y + 14, z + 14, Blocks.air);
		world.setBlock(x + 2, y + 14, z + 15, Blocks.mob_spawner);
		TileEntityMobSpawner spawner2 = (TileEntityMobSpawner)world.getTileEntity(x + 2, y + 14, z + 15);
		spawner2.func_145881_a().setEntityName("Zombie");
		world.setBlock(x + 2, y + 14, z + 16, Blocks.sandstone);
		world.setBlock(x + 2, y + 14, z + 17, Blocks.air);
		world.setBlock(x + 2, y + 14, z + 18, Blocks.air);
		world.setBlock(x + 2, y + 14, z + 19, Blocks.air);
		world.setBlock(x + 2, y + 14, z + 20, Blocks.sandstone);
		world.setBlock(x + 2, y + 15, z + 0, Blocks.air);
		world.setBlock(x + 2, y + 15, z + 1, Blocks.air);
		world.setBlock(x + 2, y + 15, z + 2, Blocks.sandstone);
		world.setBlock(x + 2, y + 15, z + 3, Blocks.sandstone);
		world.setBlock(x + 2, y + 15, z + 4, Blocks.sandstone);
		world.setBlock(x + 2, y + 15, z + 5, Blocks.sandstone);
		world.setBlock(x + 2, y + 15, z + 6, Blocks.sandstone);
		world.setBlock(x + 2, y + 15, z + 7, Blocks.sandstone);
		world.setBlock(x + 2, y + 15, z + 8, Blocks.sandstone);
		world.setBlock(x + 2, y + 15, z + 9, Blocks.sandstone);
		world.setBlock(x + 2, y + 15, z + 10, Blocks.sandstone);
		world.setBlock(x + 2, y + 15, z + 11, Blocks.sandstone);
		world.setBlock(x + 2, y + 15, z + 12, Blocks.sandstone);
		world.setBlock(x + 2, y + 15, z + 13, Blocks.sandstone);
		world.setBlock(x + 2, y + 15, z + 14, Blocks.sandstone);
		world.setBlock(x + 2, y + 15, z + 15, Blocks.sandstone);
		world.setBlock(x + 2, y + 15, z + 16, Blocks.sandstone);
		world.setBlock(x + 2, y + 15, z + 17, Blocks.air);
		world.setBlock(x + 2, y + 15, z + 18, Blocks.air);
		world.setBlock(x + 2, y + 15, z + 19, Blocks.air);
		world.setBlock(x + 2, y + 15, z + 20, Blocks.wool, 14, 2);
		world.setBlock(x + 2, y + 16, z + 0, Blocks.air);
		world.setBlock(x + 2, y + 16, z + 1, Blocks.air);
		world.setBlock(x + 2, y + 16, z + 2, Blocks.air);
		world.setBlock(x + 2, y + 16, z + 3, Blocks.air);
		world.setBlock(x + 2, y + 16, z + 4, Blocks.air);
		world.setBlock(x + 2, y + 16, z + 5, Blocks.air);
		world.setBlock(x + 2, y + 16, z + 6, Blocks.air);
		world.setBlock(x + 2, y + 16, z + 7, Blocks.air);
		world.setBlock(x + 2, y + 16, z + 8, Blocks.air);
		world.setBlock(x + 2, y + 16, z + 9, Blocks.air);
		world.setBlock(x + 2, y + 16, z + 10, Blocks.air);
		world.setBlock(x + 2, y + 16, z + 11, Blocks.air);
		world.setBlock(x + 2, y + 16, z + 12, Blocks.air);
		world.setBlock(x + 2, y + 16, z + 13, Blocks.air);
		world.setBlock(x + 2, y + 16, z + 14, Blocks.air);
		world.setBlock(x + 2, y + 16, z + 15, Blocks.air);
		world.setBlock(x + 2, y + 16, z + 16, Blocks.sandstone);
		world.setBlock(x + 2, y + 16, z + 17, Blocks.air);
		world.setBlock(x + 2, y + 16, z + 18, Blocks.air);
		world.setBlock(x + 2, y + 16, z + 19, Blocks.air);
		world.setBlock(x + 2, y + 16, z + 20, Blocks.wool, 14, 2);
		world.setBlock(x + 2, y + 17, z + 0, Blocks.air);
		world.setBlock(x + 2, y + 17, z + 1, Blocks.air);
		world.setBlock(x + 2, y + 17, z + 2, Blocks.air);
		world.setBlock(x + 2, y + 17, z + 3, Blocks.air);
		world.setBlock(x + 2, y + 17, z + 4, Blocks.air);
		world.setBlock(x + 2, y + 17, z + 5, Blocks.air);
		world.setBlock(x + 2, y + 17, z + 6, Blocks.air);
		world.setBlock(x + 2, y + 17, z + 7, Blocks.air);
		world.setBlock(x + 2, y + 17, z + 8, Blocks.air);
		world.setBlock(x + 2, y + 17, z + 9, Blocks.air);
		world.setBlock(x + 2, y + 17, z + 10, Blocks.air);
		world.setBlock(x + 2, y + 17, z + 11, Blocks.air);
		world.setBlock(x + 2, y + 17, z + 12, Blocks.air);
		world.setBlock(x + 2, y + 17, z + 13, Blocks.air);
		world.setBlock(x + 2, y + 17, z + 14, Blocks.air);
		world.setBlock(x + 2, y + 17, z + 15, Blocks.air);
		world.setBlock(x + 2, y + 17, z + 16, Blocks.sandstone);
		world.setBlock(x + 2, y + 17, z + 17, Blocks.air);
		world.setBlock(x + 2, y + 17, z + 18, Blocks.air);
		world.setBlock(x + 2, y + 17, z + 19, Blocks.air);
		world.setBlock(x + 2, y + 17, z + 20, Blocks.sandstone, 1, 2);
		world.setBlock(x + 2, y + 18, z + 0, Blocks.air);
		world.setBlock(x + 2, y + 18, z + 1, Blocks.air);
		world.setBlock(x + 2, y + 18, z + 2, Blocks.air);
		world.setBlock(x + 2, y + 18, z + 3, Blocks.air);
		world.setBlock(x + 2, y + 18, z + 4, Blocks.air);
		world.setBlock(x + 2, y + 18, z + 5, Blocks.air);
		world.setBlock(x + 2, y + 18, z + 6, Blocks.air);
		world.setBlock(x + 2, y + 18, z + 7, Blocks.air);
		world.setBlock(x + 2, y + 18, z + 8, Blocks.air);
		world.setBlock(x + 2, y + 18, z + 9, Blocks.air);
		world.setBlock(x + 2, y + 18, z + 10, Blocks.air);
		world.setBlock(x + 2, y + 18, z + 11, Blocks.air);
		world.setBlock(x + 2, y + 18, z + 12, Blocks.air);
		world.setBlock(x + 2, y + 18, z + 13, Blocks.air);
		world.setBlock(x + 2, y + 18, z + 14, Blocks.air);
		world.setBlock(x + 2, y + 18, z + 15, Blocks.air);
		world.setBlock(x + 2, y + 18, z + 16, Blocks.sandstone);
		world.setBlock(x + 2, y + 18, z + 17, Blocks.air);
		world.setBlock(x + 2, y + 18, z + 18, Blocks.air);
		world.setBlock(x + 2, y + 18, z + 19, Blocks.air);
		world.setBlock(x + 2, y + 18, z + 20, Blocks.wool, 14, 2);
		world.setBlock(x + 2, y + 19, z + 0, Blocks.air);
		world.setBlock(x + 2, y + 19, z + 1, Blocks.air);
		world.setBlock(x + 2, y + 19, z + 2, Blocks.air);
		world.setBlock(x + 2, y + 19, z + 3, Blocks.air);
		world.setBlock(x + 2, y + 19, z + 4, Blocks.air);
		world.setBlock(x + 2, y + 19, z + 5, Blocks.air);
		world.setBlock(x + 2, y + 19, z + 6, Blocks.air);
		world.setBlock(x + 2, y + 19, z + 7, Blocks.air);
		world.setBlock(x + 2, y + 19, z + 8, Blocks.air);
		world.setBlock(x + 2, y + 19, z + 9, Blocks.air);
		world.setBlock(x + 2, y + 19, z + 10, Blocks.air);
		world.setBlock(x + 2, y + 19, z + 11, Blocks.air);
		world.setBlock(x + 2, y + 19, z + 12, Blocks.air);
		world.setBlock(x + 2, y + 19, z + 13, Blocks.air);
		world.setBlock(x + 2, y + 19, z + 14, Blocks.air);
		world.setBlock(x + 2, y + 19, z + 15, Blocks.air);
		world.setBlock(x + 2, y + 19, z + 16, Blocks.sandstone);
		world.setBlock(x + 2, y + 19, z + 17, Blocks.air);
		world.setBlock(x + 2, y + 19, z + 18, Blocks.air);
		world.setBlock(x + 2, y + 19, z + 19, Blocks.air);
		world.setBlock(x + 2, y + 19, z + 20, Blocks.sandstone, 1, 2);
		world.setBlock(x + 2, y + 20, z + 0, Blocks.air);
		world.setBlock(x + 2, y + 20, z + 1, Blocks.air);
		world.setBlock(x + 2, y + 20, z + 2, Blocks.air);
		world.setBlock(x + 2, y + 20, z + 3, Blocks.air);
		world.setBlock(x + 2, y + 20, z + 4, Blocks.air);
		world.setBlock(x + 2, y + 20, z + 5, Blocks.air);
		world.setBlock(x + 2, y + 20, z + 6, Blocks.air);
		world.setBlock(x + 2, y + 20, z + 7, Blocks.air);
		world.setBlock(x + 2, y + 20, z + 8, Blocks.air);
		world.setBlock(x + 2, y + 20, z + 9, Blocks.air);
		world.setBlock(x + 2, y + 20, z + 10, Blocks.air);
		world.setBlock(x + 2, y + 20, z + 11, Blocks.air);
		world.setBlock(x + 2, y + 20, z + 12, Blocks.air);
		world.setBlock(x + 2, y + 20, z + 13, Blocks.air);
		world.setBlock(x + 2, y + 20, z + 14, Blocks.air);
		world.setBlock(x + 2, y + 20, z + 15, Blocks.air);
		world.setBlock(x + 2, y + 20, z + 16, Blocks.sandstone);
		world.setBlock(x + 2, y + 20, z + 17, Blocks.air);
		world.setBlock(x + 2, y + 20, z + 18, Blocks.air);
		world.setBlock(x + 2, y + 20, z + 19, Blocks.air);
		world.setBlock(x + 2, y + 20, z + 20, Blocks.wool, 14, 2);
		world.setBlock(x + 2, y + 21, z + 0, Blocks.air);
		world.setBlock(x + 2, y + 21, z + 1, Blocks.air);
		world.setBlock(x + 2, y + 21, z + 2, Blocks.air);
		world.setBlock(x + 2, y + 21, z + 3, Blocks.air);
		world.setBlock(x + 2, y + 21, z + 4, Blocks.air);
		world.setBlock(x + 2, y + 21, z + 5, Blocks.air);
		world.setBlock(x + 2, y + 21, z + 6, Blocks.air);
		world.setBlock(x + 2, y + 21, z + 7, Blocks.air);
		world.setBlock(x + 2, y + 21, z + 8, Blocks.air);
		world.setBlock(x + 2, y + 21, z + 9, Blocks.air);
		world.setBlock(x + 2, y + 21, z + 10, Blocks.air);
		world.setBlock(x + 2, y + 21, z + 11, Blocks.air);
		world.setBlock(x + 2, y + 21, z + 12, Blocks.air);
		world.setBlock(x + 2, y + 21, z + 13, Blocks.air);
		world.setBlock(x + 2, y + 21, z + 14, Blocks.air);
		world.setBlock(x + 2, y + 21, z + 15, Blocks.air);
		world.setBlock(x + 2, y + 21, z + 16, Blocks.sandstone);
		world.setBlock(x + 2, y + 21, z + 17, Blocks.air);
		world.setBlock(x + 2, y + 21, z + 18, Blocks.air);
		world.setBlock(x + 2, y + 21, z + 19, Blocks.air);
		world.setBlock(x + 2, y + 21, z + 20, Blocks.sandstone, 2, 2);
		world.setBlock(x + 2, y + 22, z + 0, Blocks.air);
		world.setBlock(x + 2, y + 22, z + 1, Blocks.air);
		world.setBlock(x + 2, y + 22, z + 2, Blocks.air);
		world.setBlock(x + 2, y + 22, z + 3, Blocks.air);
		world.setBlock(x + 2, y + 22, z + 4, Blocks.air);
		world.setBlock(x + 2, y + 22, z + 5, Blocks.air);
		world.setBlock(x + 2, y + 22, z + 6, Blocks.air);
		world.setBlock(x + 2, y + 22, z + 7, Blocks.air);
		world.setBlock(x + 2, y + 22, z + 8, Blocks.air);
		world.setBlock(x + 2, y + 22, z + 9, Blocks.air);
		world.setBlock(x + 2, y + 22, z + 10, Blocks.air);
		world.setBlock(x + 2, y + 22, z + 11, Blocks.air);
		world.setBlock(x + 2, y + 22, z + 12, Blocks.air);
		world.setBlock(x + 2, y + 22, z + 13, Blocks.air);
		world.setBlock(x + 2, y + 22, z + 14, Blocks.air);
		world.setBlock(x + 2, y + 22, z + 15, Blocks.air);
		world.setBlock(x + 2, y + 22, z + 16, Blocks.sandstone);
		world.setBlock(x + 2, y + 22, z + 17, Blocks.sandstone);
		world.setBlock(x + 2, y + 22, z + 18, Blocks.sandstone);
		world.setBlock(x + 2, y + 22, z + 19, Blocks.sandstone);
		world.setBlock(x + 2, y + 22, z + 20, Blocks.sandstone);
		world.setBlock(x + 2, y + 23, z + 0, Blocks.air);
		world.setBlock(x + 2, y + 23, z + 1, Blocks.air);
		world.setBlock(x + 2, y + 23, z + 2, Blocks.air);
		world.setBlock(x + 2, y + 23, z + 3, Blocks.air);
		world.setBlock(x + 2, y + 23, z + 4, Blocks.air);
		world.setBlock(x + 2, y + 23, z + 5, Blocks.air);
		world.setBlock(x + 2, y + 23, z + 6, Blocks.air);
		world.setBlock(x + 2, y + 23, z + 7, Blocks.air);
		world.setBlock(x + 2, y + 23, z + 8, Blocks.air);

		generate2(world, rand, x, y, z);
		return true;
	}

	public boolean generate2(World world, Random rand, int x, int y, int z)
	{
		world.setBlock(x + 2, y + 23, z + 9, Blocks.air);
		world.setBlock(x + 2, y + 23, z + 10, Blocks.air);
		world.setBlock(x + 2, y + 23, z + 11, Blocks.air);
		world.setBlock(x + 2, y + 23, z + 12, Blocks.air);
		world.setBlock(x + 2, y + 23, z + 13, Blocks.air);
		world.setBlock(x + 2, y + 23, z + 14, Blocks.air);
		world.setBlock(x + 2, y + 23, z + 15, Blocks.air);
		world.setBlock(x + 2, y + 23, z + 16, Blocks.sandstone_stairs, 2, 2);
		world.setBlock(x + 2, y + 23, z + 17, Blocks.sandstone);
		world.setBlock(x + 2, y + 23, z + 18, Blocks.sandstone);
		world.setBlock(x + 2, y + 23, z + 19, Blocks.sandstone);
		world.setBlock(x + 2, y + 23, z + 20, Blocks.sandstone_stairs, 3, 2);
		world.setBlock(x + 3, y + 0, z + 0, Blocks.sandstone);
		world.setBlock(x + 3, y + 0, z + 1, Blocks.sandstone);
		world.setBlock(x + 3, y + 0, z + 2, Blocks.sandstone);
		world.setBlock(x + 3, y + 0, z + 3, Blocks.sandstone);
		world.setBlock(x + 3, y + 0, z + 4, Blocks.sandstone);
		world.setBlock(x + 3, y + 0, z + 5, Blocks.sandstone);
		world.setBlock(x + 3, y + 0, z + 6, Blocks.sandstone);
		world.setBlock(x + 3, y + 0, z + 7, Blocks.sandstone);
		world.setBlock(x + 3, y + 0, z + 8, Blocks.sandstone);
		world.setBlock(x + 3, y + 0, z + 9, Blocks.sandstone);
		world.setBlock(x + 3, y + 0, z + 10, Blocks.sandstone);
		world.setBlock(x + 3, y + 0, z + 11, Blocks.sandstone);
		world.setBlock(x + 3, y + 0, z + 12, Blocks.sandstone);
		world.setBlock(x + 3, y + 0, z + 13, Blocks.sandstone);
		world.setBlock(x + 3, y + 0, z + 14, Blocks.sandstone);
		world.setBlock(x + 3, y + 0, z + 15, Blocks.sandstone);
		world.setBlock(x + 3, y + 0, z + 16, Blocks.sandstone);
		world.setBlock(x + 3, y + 0, z + 17, Blocks.sandstone);
		world.setBlock(x + 3, y + 0, z + 18, Blocks.sandstone);
		world.setBlock(x + 3, y + 0, z + 19, Blocks.sandstone);
		world.setBlock(x + 3, y + 0, z + 20, Blocks.sandstone);
		world.setBlock(x + 3, y + 1, z + 0, Blocks.sandstone);
		world.setBlock(x + 3, y + 1, z + 1, Blocks.sandstone);
		world.setBlock(x + 3, y + 1, z + 2, Blocks.sandstone);
		world.setBlock(x + 3, y + 1, z + 3, Blocks.sandstone);
		world.setBlock(x + 3, y + 1, z + 4, Blocks.sandstone);
		world.setBlock(x + 3, y + 1, z + 5, Blocks.sandstone);
		world.setBlock(x + 3, y + 1, z + 6, Blocks.sandstone);
		world.setBlock(x + 3, y + 1, z + 7, Blocks.sandstone);
		world.setBlock(x + 3, y + 1, z + 8, Blocks.sandstone);
		world.setBlock(x + 3, y + 1, z + 9, Blocks.sandstone);
		world.setBlock(x + 3, y + 1, z + 10, Blocks.sandstone);
		world.setBlock(x + 3, y + 1, z + 11, Blocks.sandstone);
		world.setBlock(x + 3, y + 1, z + 12, Blocks.sandstone);
		world.setBlock(x + 3, y + 1, z + 13, Blocks.sandstone);
		world.setBlock(x + 3, y + 1, z + 14, Blocks.sandstone);
		world.setBlock(x + 3, y + 1, z + 15, Blocks.sandstone);
		world.setBlock(x + 3, y + 1, z + 16, Blocks.sandstone);
		world.setBlock(x + 3, y + 1, z + 17, Blocks.sandstone);
		world.setBlock(x + 3, y + 1, z + 18, Blocks.sandstone);
		world.setBlock(x + 3, y + 1, z + 19, Blocks.sandstone);
		world.setBlock(x + 3, y + 1, z + 20, Blocks.sandstone);
		world.setBlock(x + 3, y + 2, z + 0, Blocks.sandstone);
		world.setBlock(x + 3, y + 2, z + 1, Blocks.sandstone);
		world.setBlock(x + 3, y + 2, z + 2, Blocks.sandstone);
		world.setBlock(x + 3, y + 2, z + 3, Blocks.sandstone);
		world.setBlock(x + 3, y + 2, z + 4, Blocks.sandstone);
		world.setBlock(x + 3, y + 2, z + 5, Blocks.sandstone);
		world.setBlock(x + 3, y + 2, z + 6, Blocks.sandstone);
		world.setBlock(x + 3, y + 2, z + 7, Blocks.sandstone);
		world.setBlock(x + 3, y + 2, z + 8, Blocks.sandstone);
		world.setBlock(x + 3, y + 2, z + 9, Blocks.sandstone);
		world.setBlock(x + 3, y + 2, z + 10, Blocks.sandstone);
		world.setBlock(x + 3, y + 2, z + 11, Blocks.sandstone);
		world.setBlock(x + 3, y + 2, z + 12, Blocks.sandstone);
		world.setBlock(x + 3, y + 2, z + 13, Blocks.sandstone);
		world.setBlock(x + 3, y + 2, z + 14, Blocks.sandstone);
		world.setBlock(x + 3, y + 2, z + 15, Blocks.sandstone);
		world.setBlock(x + 3, y + 2, z + 16, Blocks.sandstone);
		world.setBlock(x + 3, y + 2, z + 17, Blocks.sandstone);
		world.setBlock(x + 3, y + 2, z + 18, Blocks.sandstone);
		world.setBlock(x + 3, y + 2, z + 19, Blocks.sandstone);
		world.setBlock(x + 3, y + 2, z + 20, Blocks.sandstone);
		world.setBlock(x + 3, y + 3, z + 0, Blocks.sandstone);
		world.setBlock(x + 3, y + 3, z + 1, Blocks.sandstone);
		world.setBlock(x + 3, y + 3, z + 2, Blocks.sandstone);
		world.setBlock(x + 3, y + 3, z + 3, Blocks.sandstone);
		world.setBlock(x + 3, y + 3, z + 4, Blocks.sandstone);
		world.setBlock(x + 3, y + 3, z + 5, Blocks.sandstone);
		world.setBlock(x + 3, y + 3, z + 6, Blocks.sandstone);
		world.setBlock(x + 3, y + 3, z + 7, Blocks.sandstone);
		world.setBlock(x + 3, y + 3, z + 8, Blocks.sandstone);
		world.setBlock(x + 3, y + 3, z + 9, Blocks.sandstone);
		world.setBlock(x + 3, y + 3, z + 10, Blocks.sandstone);
		world.setBlock(x + 3, y + 3, z + 11, Blocks.sandstone);
		world.setBlock(x + 3, y + 3, z + 12, Blocks.sandstone);
		world.setBlock(x + 3, y + 3, z + 13, Blocks.sandstone);
		world.setBlock(x + 3, y + 3, z + 14, Blocks.sandstone);
		world.setBlock(x + 3, y + 3, z + 15, Blocks.sandstone);
		world.setBlock(x + 3, y + 3, z + 16, Blocks.sandstone);
		world.setBlock(x + 3, y + 3, z + 17, Blocks.sandstone);
		world.setBlock(x + 3, y + 3, z + 18, Blocks.sandstone);
		world.setBlock(x + 3, y + 3, z + 19, Blocks.sandstone);
		world.setBlock(x + 3, y + 3, z + 20, Blocks.sandstone);
		world.setBlock(x + 3, y + 4, z + 0, Blocks.sandstone);
		world.setBlock(x + 3, y + 4, z + 1, Blocks.sandstone);
		world.setBlock(x + 3, y + 4, z + 2, Blocks.sandstone);
		world.setBlock(x + 3, y + 4, z + 3, Blocks.sandstone);
		world.setBlock(x + 3, y + 4, z + 4, Blocks.sandstone);
		world.setBlock(x + 3, y + 4, z + 5, Blocks.sandstone);
		world.setBlock(x + 3, y + 4, z + 6, Blocks.sandstone);
		world.setBlock(x + 3, y + 4, z + 7, Blocks.sandstone);
		world.setBlock(x + 3, y + 4, z + 8, Blocks.sandstone);
		world.setBlock(x + 3, y + 4, z + 9, Blocks.sandstone);
		world.setBlock(x + 3, y + 4, z + 10, Blocks.sandstone);
		world.setBlock(x + 3, y + 4, z + 11, Blocks.sandstone);
		world.setBlock(x + 3, y + 4, z + 12, Blocks.sandstone);
		world.setBlock(x + 3, y + 4, z + 13, Blocks.sandstone);
		world.setBlock(x + 3, y + 4, z + 14, Blocks.sandstone);
		world.setBlock(x + 3, y + 4, z + 15, Blocks.sandstone);
		world.setBlock(x + 3, y + 4, z + 16, Blocks.sandstone);
		world.setBlock(x + 3, y + 4, z + 17, Blocks.sandstone);
		world.setBlock(x + 3, y + 4, z + 18, Blocks.sandstone);
		world.setBlock(x + 3, y + 4, z + 19, Blocks.sandstone);
		world.setBlock(x + 3, y + 4, z + 20, Blocks.sandstone);
		world.setBlock(x + 3, y + 5, z + 0, Blocks.sandstone);
		world.setBlock(x + 3, y + 5, z + 1, Blocks.sandstone);
		world.setBlock(x + 3, y + 5, z + 2, Blocks.sandstone);
		world.setBlock(x + 3, y + 5, z + 3, Blocks.sandstone);
		world.setBlock(x + 3, y + 5, z + 4, Blocks.sandstone);
		world.setBlock(x + 3, y + 5, z + 5, Blocks.sandstone);
		world.setBlock(x + 3, y + 5, z + 6, Blocks.sandstone);
		world.setBlock(x + 3, y + 5, z + 7, Blocks.sandstone);
		world.setBlock(x + 3, y + 5, z + 8, Blocks.sandstone);
		world.setBlock(x + 3, y + 5, z + 9, Blocks.sandstone);
		world.setBlock(x + 3, y + 5, z + 10, Blocks.sandstone);
		world.setBlock(x + 3, y + 5, z + 11, Blocks.sandstone);
		world.setBlock(x + 3, y + 5, z + 12, Blocks.sandstone);
		world.setBlock(x + 3, y + 5, z + 13, Blocks.sandstone);
		world.setBlock(x + 3, y + 5, z + 14, Blocks.sandstone);
		world.setBlock(x + 3, y + 5, z + 15, Blocks.sandstone);
		world.setBlock(x + 3, y + 5, z + 16, Blocks.sandstone);
		world.setBlock(x + 3, y + 5, z + 17, Blocks.sandstone);
		world.setBlock(x + 3, y + 5, z + 18, Blocks.sandstone);
		world.setBlock(x + 3, y + 5, z + 19, Blocks.sandstone);
		world.setBlock(x + 3, y + 5, z + 20, Blocks.sandstone);
		world.setBlock(x + 3, y + 6, z + 0, Blocks.sandstone);
		world.setBlock(x + 3, y + 6, z + 1, Blocks.sandstone);
		world.setBlock(x + 3, y + 6, z + 2, Blocks.sandstone);
		world.setBlock(x + 3, y + 6, z + 3, Blocks.sandstone);
		world.setBlock(x + 3, y + 6, z + 4, Blocks.sandstone);
		world.setBlock(x + 3, y + 6, z + 5, Blocks.sandstone);
		world.setBlock(x + 3, y + 6, z + 6, Blocks.sandstone);
		world.setBlock(x + 3, y + 6, z + 7, Blocks.sandstone);
		world.setBlock(x + 3, y + 6, z + 8, Blocks.sandstone);
		world.setBlock(x + 3, y + 6, z + 9, Blocks.sandstone);
		world.setBlock(x + 3, y + 6, z + 10, Blocks.sandstone);
		world.setBlock(x + 3, y + 6, z + 11, Blocks.sandstone);
		world.setBlock(x + 3, y + 6, z + 12, Blocks.sandstone);
		world.setBlock(x + 3, y + 6, z + 13, Blocks.sandstone);
		world.setBlock(x + 3, y + 6, z + 14, Blocks.sandstone);
		world.setBlock(x + 3, y + 6, z + 15, Blocks.sandstone);
		world.setBlock(x + 3, y + 6, z + 16, Blocks.sandstone);
		world.setBlock(x + 3, y + 6, z + 17, Blocks.sandstone);
		world.setBlock(x + 3, y + 6, z + 18, Blocks.sandstone);
		world.setBlock(x + 3, y + 6, z + 19, Blocks.sandstone);
		world.setBlock(x + 3, y + 6, z + 20, Blocks.sandstone);
		world.setBlock(x + 3, y + 7, z + 0, Blocks.sandstone);
		world.setBlock(x + 3, y + 7, z + 1, Blocks.sandstone);
		world.setBlock(x + 3, y + 7, z + 2, Blocks.sandstone);
		world.setBlock(x + 3, y + 7, z + 3, Blocks.sandstone);
		world.setBlock(x + 3, y + 7, z + 4, Blocks.sandstone);
		world.setBlock(x + 3, y + 7, z + 5, Blocks.sandstone);
		world.setBlock(x + 3, y + 7, z + 6, Blocks.sandstone);
		world.setBlock(x + 3, y + 7, z + 7, Blocks.sandstone);
		world.setBlock(x + 3, y + 7, z + 8, Blocks.sandstone);
		world.setBlock(x + 3, y + 7, z + 9, Blocks.sandstone);
		world.setBlock(x + 3, y + 7, z + 10, Blocks.sandstone);
		world.setBlock(x + 3, y + 7, z + 11, Blocks.sandstone);
		world.setBlock(x + 3, y + 7, z + 12, Blocks.sandstone);
		world.setBlock(x + 3, y + 7, z + 13, Blocks.sandstone);
		world.setBlock(x + 3, y + 7, z + 14, Blocks.sandstone);
		world.setBlock(x + 3, y + 7, z + 15, Blocks.sandstone);
		world.setBlock(x + 3, y + 7, z + 16, Blocks.sandstone);
		world.setBlock(x + 3, y + 7, z + 17, Blocks.sandstone);
		world.setBlock(x + 3, y + 7, z + 18, Blocks.sandstone);
		world.setBlock(x + 3, y + 7, z + 19, Blocks.sandstone);
		world.setBlock(x + 3, y + 7, z + 20, Blocks.sandstone);
		world.setBlock(x + 3, y + 8, z + 0, Blocks.sandstone);
		world.setBlock(x + 3, y + 8, z + 1, Blocks.sandstone);
		world.setBlock(x + 3, y + 8, z + 2, Blocks.sandstone);
		world.setBlock(x + 3, y + 8, z + 3, Blocks.sandstone);
		world.setBlock(x + 3, y + 8, z + 4, Blocks.sandstone);
		world.setBlock(x + 3, y + 8, z + 5, Blocks.sandstone);
		world.setBlock(x + 3, y + 8, z + 6, Blocks.sandstone);
		world.setBlock(x + 3, y + 8, z + 7, Blocks.sandstone);
		world.setBlock(x + 3, y + 8, z + 8, Blocks.sandstone);
		world.setBlock(x + 3, y + 8, z + 9, Blocks.sandstone);
		world.setBlock(x + 3, y + 8, z + 10, Blocks.sandstone);
		world.setBlock(x + 3, y + 8, z + 11, Blocks.sandstone);
		world.setBlock(x + 3, y + 8, z + 12, Blocks.sandstone);
		world.setBlock(x + 3, y + 8, z + 13, Blocks.sandstone);
		world.setBlock(x + 3, y + 8, z + 14, Blocks.sandstone);
		world.setBlock(x + 3, y + 8, z + 15, Blocks.sandstone);
		world.setBlock(x + 3, y + 8, z + 16, Blocks.sandstone);
		world.setBlock(x + 3, y + 8, z + 17, Blocks.sandstone);
		world.setBlock(x + 3, y + 8, z + 18, Blocks.sandstone);
		world.setBlock(x + 3, y + 8, z + 19, Blocks.sandstone);
		world.setBlock(x + 3, y + 8, z + 20, Blocks.sandstone);
		world.setBlock(x + 3, y + 9, z + 0, Blocks.sandstone);
		world.setBlock(x + 3, y + 9, z + 1, Blocks.sandstone);
		world.setBlock(x + 3, y + 9, z + 2, Blocks.sandstone);
		world.setBlock(x + 3, y + 9, z + 3, Blocks.sandstone);
		world.setBlock(x + 3, y + 9, z + 4, Blocks.sandstone);
		world.setBlock(x + 3, y + 9, z + 5, Blocks.sandstone);
		world.setBlock(x + 3, y + 9, z + 6, Blocks.sandstone);
		world.setBlock(x + 3, y + 9, z + 7, Blocks.sandstone);
		world.setBlock(x + 3, y + 9, z + 8, Blocks.sandstone);
		world.setBlock(x + 3, y + 9, z + 9, Blocks.sandstone);
		world.setBlock(x + 3, y + 9, z + 10, Blocks.sandstone);
		world.setBlock(x + 3, y + 9, z + 11, Blocks.sandstone);
		world.setBlock(x + 3, y + 9, z + 12, Blocks.sandstone);
		world.setBlock(x + 3, y + 9, z + 13, Blocks.sandstone);
		world.setBlock(x + 3, y + 9, z + 14, Blocks.sandstone);
		world.setBlock(x + 3, y + 9, z + 15, Blocks.sandstone);
		world.setBlock(x + 3, y + 9, z + 16, Blocks.sandstone);
		world.setBlock(x + 3, y + 9, z + 17, Blocks.sandstone);
		world.setBlock(x + 3, y + 9, z + 18, Blocks.sandstone);
		world.setBlock(x + 3, y + 9, z + 19, Blocks.sandstone);
		world.setBlock(x + 3, y + 9, z + 20, Blocks.sandstone);
		world.setBlock(x + 3, y + 10, z + 0, Blocks.sandstone);
		world.setBlock(x + 3, y + 10, z + 1, Blocks.sandstone);
		world.setBlock(x + 3, y + 10, z + 2, Blocks.sandstone);
		world.setBlock(x + 3, y + 10, z + 3, Blocks.sandstone);
		world.setBlock(x + 3, y + 10, z + 4, Blocks.sandstone);
		world.setBlock(x + 3, y + 10, z + 5, Blocks.sandstone);
		world.setBlock(x + 3, y + 10, z + 6, Blocks.sandstone);
		world.setBlock(x + 3, y + 10, z + 7, Blocks.sandstone);
		world.setBlock(x + 3, y + 10, z + 8, Blocks.sandstone);
		world.setBlock(x + 3, y + 10, z + 9, Blocks.sandstone);
		world.setBlock(x + 3, y + 10, z + 10, Blocks.sandstone);
		world.setBlock(x + 3, y + 10, z + 11, Blocks.sandstone);
		world.setBlock(x + 3, y + 10, z + 12, Blocks.sandstone);
		world.setBlock(x + 3, y + 10, z + 13, Blocks.sandstone);
		world.setBlock(x + 3, y + 10, z + 14, Blocks.sandstone);
		world.setBlock(x + 3, y + 10, z + 15, Blocks.sandstone);
		world.setBlock(x + 3, y + 10, z + 16, Blocks.sandstone);
		world.setBlock(x + 3, y + 10, z + 17, Blocks.sandstone);
